[2022-09-05 13:56:10,138: INFO/MainProcess] Task services.tasks.start_web_scraping_indeed[d780cbed-219b-451b-8fbf-f09eb09d3201] received
[2022-09-05 13:56:18,987: INFO/ForkPoolWorker-1] None Professional Development Specialist – McKinsey Digital (Buil... has been added to the database
[2022-09-05 13:56:18,988: INFO/ForkPoolWorker-1] None Office Services Coordinator has been added to the database
[2022-09-05 13:56:18,989: INFO/ForkPoolWorker-1] None Data Analyst has been added to the database
[2022-09-05 13:56:18,989: INFO/ForkPoolWorker-1] None Engagement Services Administrator - with Portuguese or Manda... has been added to the database
[2022-09-05 13:56:18,990: INFO/ForkPoolWorker-1] None Knowledge Analyst - Delivery Modernization Hub - McKinsey Di... has been added to the database
[2022-09-05 13:56:18,990: INFO/ForkPoolWorker-1] None Professional Development Manager – McKinsey Digital (Build H... has been added to the database
[2022-09-05 13:56:18,991: INFO/ForkPoolWorker-1] None Senior Implementation Facilitator - FIG, McKinsey Implementa... has been added to the database
[2022-09-05 13:56:18,991: INFO/ForkPoolWorker-1] None Business Presentation Specialist (Trainee) has been added to the database
[2022-09-05 13:56:18,992: INFO/ForkPoolWorker-1] None Professional Development Manager - McKinsey Transformation has been added to the database
[2022-09-05 13:56:18,992: INFO/ForkPoolWorker-1] None Receptionist has been added to the database
[2022-09-05 13:56:18,992: INFO/ForkPoolWorker-1] None Solution Delivery Analyst - Catalyst Zero has been added to the database
[2022-09-05 13:56:18,993: INFO/ForkPoolWorker-1] None Professional Development Manager - McKinsey Digital has been added to the database
[2022-09-05 13:56:18,993: INFO/ForkPoolWorker-1] None Senior Finance Associate - Payments has been added to the database
[2022-09-05 13:56:18,994: INFO/ForkPoolWorker-1] None Investment Operations Manager and Trust Associate has been added to the database
[2022-09-05 13:56:18,994: INFO/ForkPoolWorker-1] None Research Science Analyst - Panorama Financial Institutions C... has been added to the database
[2022-09-05 13:56:18,994: INFO/ForkPoolWorker-1] None is not active
[2022-09-05 13:56:18,995: INFO/ForkPoolWorker-1] Task services.tasks.start_web_scraping_indeed[d780cbed-219b-451b-8fbf-f09eb09d3201] succeeded in 8.855316504021175s: None
[2022-09-05 13:59:11,970: INFO/MainProcess] Connected to redis://localhost:6379//
[2022-09-05 13:59:11,976: INFO/MainProcess] mingle: searching for neighbors
[2022-09-05 13:59:12,987: INFO/MainProcess] mingle: all alone
[2022-09-05 13:59:13,011: WARNING/MainProcess] /run/media/oyewunmio/STORAGE/System-Application/anaconda3/envs/Django_env/lib/python3.10/site-packages/celery/fixups/django.py:203: UserWarning: Using settings.DEBUG leads to a memory
            leak, never use this setting in production environments!
  warnings.warn('''Using settings.DEBUG leads to a memory

[2022-09-05 13:59:13,011: INFO/MainProcess] celery@Asteria ready.
[2022-09-05 14:00:25,896: INFO/MainProcess] Task services.tasks.start_web_scraping_indeed[67c2fe55-717b-42c8-a58d-c1531558176c] received
[2022-09-05 14:00:31,985: INFO/ForkPoolWorker-1] 4 Professional Development Specialist – McKinsey Digital (Buil... has been added to the database
[2022-09-05 14:00:32,117: INFO/ForkPoolWorker-1] 5 Office Services Coordinator has been added to the database
[2022-09-05 14:00:32,249: INFO/ForkPoolWorker-1] 6 Data Analyst has been added to the database
[2022-09-05 14:00:32,387: INFO/ForkPoolWorker-1] 7 Engagement Services Administrator - with Portuguese or Manda... has been added to the database
[2022-09-05 14:00:32,519: INFO/ForkPoolWorker-1] 8 Knowledge Analyst - Delivery Modernization Hub - McKinsey Di... has been added to the database
[2022-09-05 14:00:32,685: INFO/ForkPoolWorker-1] 9 Professional Development Manager – McKinsey Digital (Build H... has been added to the database
[2022-09-05 14:00:32,838: INFO/ForkPoolWorker-1] 10 Senior Implementation Facilitator - FIG, McKinsey Implementa... has been added to the database
[2022-09-05 14:00:32,982: INFO/ForkPoolWorker-1] 11 Business Presentation Specialist (Trainee) has been added to the database
[2022-09-05 14:00:33,137: INFO/ForkPoolWorker-1] 12 Professional Development Manager - McKinsey Transformation has been added to the database
[2022-09-05 14:00:33,285: INFO/ForkPoolWorker-1] 13 Receptionist has been added to the database
[2022-09-05 14:00:33,432: INFO/ForkPoolWorker-1] 14 Solution Delivery Analyst - Catalyst Zero has been added to the database
[2022-09-05 14:00:34,748: INFO/ForkPoolWorker-1] 15 Professional Development Manager - McKinsey Digital has been added to the database
[2022-09-05 14:00:34,903: INFO/ForkPoolWorker-1] 16 Senior Finance Associate - Payments has been added to the database
[2022-09-05 14:00:35,386: INFO/ForkPoolWorker-1] 17 Investment Operations Manager and Trust Associate has been added to the database
[2022-09-05 14:00:35,529: INFO/ForkPoolWorker-1] 18 Research Science Analyst - Panorama Financial Institutions C... has been added to the database
[2022-09-05 14:00:35,529: INFO/ForkPoolWorker-1] None is not active
[2022-09-05 14:00:35,532: INFO/ForkPoolWorker-1] Task services.tasks.start_web_scraping_indeed[67c2fe55-717b-42c8-a58d-c1531558176c] succeeded in 9.633741003024625s: None
[2022-09-06 06:39:53,849: INFO/MainProcess] Task celery.backend_cleanup[8d5d53da-86c7-4bea-b71e-9fe167df1115] received
[2022-09-06 06:39:54,014: INFO/ForkPoolWorker-1] Task celery.backend_cleanup[8d5d53da-86c7-4bea-b71e-9fe167df1115] succeeded in 0.029612328042276204s: None
[2022-09-07 08:12:58,736: INFO/MainProcess] Task celery.backend_cleanup[2bab40b6-81ea-4519-aebe-25b817eec4da] received
[2022-09-07 08:12:59,014: INFO/ForkPoolWorker-1] Task celery.backend_cleanup[2bab40b6-81ea-4519-aebe-25b817eec4da] succeeded in 0.09277798602124676s: None
[2022-09-15 13:51:38,727: ERROR/MainProcess] consumer: Cannot connect to redis://localhost:6379//: Error 111 connecting to localhost:6379. Connection refused..
Trying again in 2.00 seconds... (1/100)

[2022-09-15 13:51:40,807: ERROR/MainProcess] consumer: Cannot connect to redis://localhost:6379//: Error 111 connecting to localhost:6379. Connection refused..
Trying again in 4.00 seconds... (2/100)

[2022-09-15 13:51:44,814: ERROR/MainProcess] consumer: Cannot connect to redis://localhost:6379//: Error 111 connecting to localhost:6379. Connection refused..
Trying again in 6.00 seconds... (3/100)

[2022-09-15 13:51:50,824: ERROR/MainProcess] consumer: Cannot connect to redis://localhost:6379//: Error 111 connecting to localhost:6379. Connection refused..
Trying again in 8.00 seconds... (4/100)

[2022-09-15 13:51:58,834: ERROR/MainProcess] consumer: Cannot connect to redis://localhost:6379//: Error 111 connecting to localhost:6379. Connection refused..
Trying again in 10.00 seconds... (5/100)

[2022-09-15 13:52:08,848: ERROR/MainProcess] consumer: Cannot connect to redis://localhost:6379//: Error 111 connecting to localhost:6379. Connection refused..
Trying again in 12.00 seconds... (6/100)

[2022-09-15 13:52:20,865: ERROR/MainProcess] consumer: Cannot connect to redis://localhost:6379//: Error 111 connecting to localhost:6379. Connection refused..
Trying again in 14.00 seconds... (7/100)

[2022-09-15 13:52:34,883: ERROR/MainProcess] consumer: Cannot connect to redis://localhost:6379//: Error 111 connecting to localhost:6379. Connection refused..
Trying again in 16.00 seconds... (8/100)

[2022-09-15 13:52:48,541: ERROR/MainProcess] consumer: Cannot connect to redis://localhost:6379//: Error 111 connecting to localhost:6379. Connection refused..
Trying again in 2.00 seconds... (1/100)

[2022-09-15 13:52:50,547: ERROR/MainProcess] consumer: Cannot connect to redis://localhost:6379//: Error 111 connecting to localhost:6379. Connection refused..
Trying again in 4.00 seconds... (2/100)

[2022-09-15 13:52:50,903: ERROR/MainProcess] consumer: Cannot connect to redis://localhost:6379//: Error 111 connecting to localhost:6379. Connection refused..
Trying again in 18.00 seconds... (9/100)

[2022-09-15 13:52:54,552: ERROR/MainProcess] consumer: Cannot connect to redis://localhost:6379//: Error 111 connecting to localhost:6379. Connection refused..
Trying again in 6.00 seconds... (3/100)

[2022-09-15 13:53:00,562: ERROR/MainProcess] consumer: Cannot connect to redis://localhost:6379//: Error 111 connecting to localhost:6379. Connection refused..
Trying again in 8.00 seconds... (4/100)

[2022-09-15 13:53:08,573: ERROR/MainProcess] consumer: Cannot connect to redis://localhost:6379//: Error 111 connecting to localhost:6379. Connection refused..
Trying again in 10.00 seconds... (5/100)

[2022-09-15 13:53:08,924: ERROR/MainProcess] consumer: Cannot connect to redis://localhost:6379//: Error 111 connecting to localhost:6379. Connection refused..
Trying again in 20.00 seconds... (10/100)

[2022-09-15 13:53:18,586: ERROR/MainProcess] consumer: Cannot connect to redis://localhost:6379//: Error 111 connecting to localhost:6379. Connection refused..
Trying again in 12.00 seconds... (6/100)

[2022-09-15 13:53:28,947: ERROR/MainProcess] consumer: Cannot connect to redis://localhost:6379//: Error 111 connecting to localhost:6379. Connection refused..
Trying again in 22.00 seconds... (11/100)

[2022-09-15 13:53:30,601: ERROR/MainProcess] consumer: Cannot connect to redis://localhost:6379//: Error 111 connecting to localhost:6379. Connection refused..
Trying again in 14.00 seconds... (7/100)

[2022-09-15 13:53:44,619: ERROR/MainProcess] consumer: Cannot connect to redis://localhost:6379//: Error 111 connecting to localhost:6379. Connection refused..
Trying again in 16.00 seconds... (8/100)

[2022-09-15 13:53:50,973: ERROR/MainProcess] consumer: Cannot connect to redis://localhost:6379//: Error 111 connecting to localhost:6379. Connection refused..
Trying again in 24.00 seconds... (12/100)

[2022-09-15 13:54:00,638: ERROR/MainProcess] consumer: Cannot connect to redis://localhost:6379//: Error 111 connecting to localhost:6379. Connection refused..
Trying again in 18.00 seconds... (9/100)

[2022-09-15 13:54:15,001: ERROR/MainProcess] consumer: Cannot connect to redis://localhost:6379//: Error 111 connecting to localhost:6379. Connection refused..
Trying again in 26.00 seconds... (13/100)

[2022-09-15 13:54:18,659: ERROR/MainProcess] consumer: Cannot connect to redis://localhost:6379//: Error 111 connecting to localhost:6379. Connection refused..
Trying again in 20.00 seconds... (10/100)

[2022-09-15 13:54:38,682: ERROR/MainProcess] consumer: Cannot connect to redis://localhost:6379//: Error 111 connecting to localhost:6379. Connection refused..
Trying again in 22.00 seconds... (11/100)

[2022-09-15 13:54:41,030: ERROR/MainProcess] consumer: Cannot connect to redis://localhost:6379//: Error 111 connecting to localhost:6379. Connection refused..
Trying again in 28.00 seconds... (14/100)

[2022-09-15 13:55:00,705: ERROR/MainProcess] consumer: Cannot connect to redis://localhost:6379//: Error 111 connecting to localhost:6379. Connection refused..
Trying again in 24.00 seconds... (12/100)

[2022-09-15 13:55:09,062: ERROR/MainProcess] consumer: Cannot connect to redis://localhost:6379//: Error 111 connecting to localhost:6379. Connection refused..
Trying again in 30.00 seconds... (15/100)

[2022-09-15 13:55:24,734: ERROR/MainProcess] consumer: Cannot connect to redis://localhost:6379//: Error 111 connecting to localhost:6379. Connection refused..
Trying again in 26.00 seconds... (13/100)

[2022-09-15 13:55:39,097: ERROR/MainProcess] consumer: Cannot connect to redis://localhost:6379//: Error 111 connecting to localhost:6379. Connection refused..
Trying again in 32.00 seconds... (16/100)

[2022-09-15 13:55:50,765: ERROR/MainProcess] consumer: Cannot connect to redis://localhost:6379//: Error 111 connecting to localhost:6379. Connection refused..
Trying again in 28.00 seconds... (14/100)

[2022-09-15 13:56:11,133: ERROR/MainProcess] consumer: Cannot connect to redis://localhost:6379//: Error 111 connecting to localhost:6379. Connection refused..
Trying again in 32.00 seconds... (16/100)

[2022-09-15 13:56:18,798: ERROR/MainProcess] consumer: Cannot connect to redis://localhost:6379//: Error 111 connecting to localhost:6379. Connection refused..
Trying again in 30.00 seconds... (15/100)

[2022-09-15 13:56:43,171: ERROR/MainProcess] consumer: Cannot connect to redis://localhost:6379//: Error 111 connecting to localhost:6379. Connection refused..
Trying again in 32.00 seconds... (16/100)

[2022-09-15 13:56:48,831: ERROR/MainProcess] consumer: Cannot connect to redis://localhost:6379//: Error 111 connecting to localhost:6379. Connection refused..
Trying again in 32.00 seconds... (16/100)

[2022-09-15 13:57:15,207: ERROR/MainProcess] consumer: Cannot connect to redis://localhost:6379//: Error 111 connecting to localhost:6379. Connection refused..
Trying again in 32.00 seconds... (16/100)

[2022-09-15 13:57:20,867: ERROR/MainProcess] consumer: Cannot connect to redis://localhost:6379//: Error 111 connecting to localhost:6379. Connection refused..
Trying again in 32.00 seconds... (16/100)

[2022-09-15 13:57:47,244: ERROR/MainProcess] consumer: Cannot connect to redis://localhost:6379//: Error 111 connecting to localhost:6379. Connection refused..
Trying again in 32.00 seconds... (16/100)

[2022-09-15 13:57:52,904: ERROR/MainProcess] consumer: Cannot connect to redis://localhost:6379//: Error 111 connecting to localhost:6379. Connection refused..
Trying again in 32.00 seconds... (16/100)

[2022-09-15 13:58:19,281: ERROR/MainProcess] consumer: Cannot connect to redis://localhost:6379//: Error 111 connecting to localhost:6379. Connection refused..
Trying again in 32.00 seconds... (16/100)

[2022-09-15 13:58:24,941: ERROR/MainProcess] consumer: Cannot connect to redis://localhost:6379//: Error 111 connecting to localhost:6379. Connection refused..
Trying again in 32.00 seconds... (16/100)

[2022-09-15 13:58:51,313: ERROR/MainProcess] consumer: Cannot connect to redis://localhost:6379//: Error 111 connecting to localhost:6379. Connection refused..
Trying again in 32.00 seconds... (16/100)

[2022-09-15 13:58:56,978: ERROR/MainProcess] consumer: Cannot connect to redis://localhost:6379//: Error 111 connecting to localhost:6379. Connection refused..
Trying again in 32.00 seconds... (16/100)

[2022-09-15 13:59:23,350: ERROR/MainProcess] consumer: Cannot connect to redis://localhost:6379//: Error 111 connecting to localhost:6379. Connection refused..
Trying again in 32.00 seconds... (16/100)

[2022-09-15 13:59:29,014: ERROR/MainProcess] consumer: Cannot connect to redis://localhost:6379//: Error 111 connecting to localhost:6379. Connection refused..
Trying again in 32.00 seconds... (16/100)

[2022-09-15 13:59:55,384: ERROR/MainProcess] consumer: Cannot connect to redis://localhost:6379//: Error 111 connecting to localhost:6379. Connection refused..
Trying again in 32.00 seconds... (16/100)

[2022-09-15 14:00:01,050: ERROR/MainProcess] consumer: Cannot connect to redis://localhost:6379//: Error 111 connecting to localhost:6379. Connection refused..
Trying again in 32.00 seconds... (16/100)

[2022-09-15 14:00:27,420: ERROR/MainProcess] consumer: Cannot connect to redis://localhost:6379//: Error 111 connecting to localhost:6379. Connection refused..
Trying again in 32.00 seconds... (16/100)

[2022-09-15 14:00:33,086: ERROR/MainProcess] consumer: Cannot connect to redis://localhost:6379//: Error 111 connecting to localhost:6379. Connection refused..
Trying again in 32.00 seconds... (16/100)

[2022-09-15 14:00:59,457: ERROR/MainProcess] consumer: Cannot connect to redis://localhost:6379//: Error 111 connecting to localhost:6379. Connection refused..
Trying again in 32.00 seconds... (16/100)

[2022-09-15 14:01:05,122: ERROR/MainProcess] consumer: Cannot connect to redis://localhost:6379//: Error 111 connecting to localhost:6379. Connection refused..
Trying again in 32.00 seconds... (16/100)

[2022-09-15 14:01:31,492: ERROR/MainProcess] consumer: Cannot connect to redis://localhost:6379//: Error 111 connecting to localhost:6379. Connection refused..
Trying again in 32.00 seconds... (16/100)

[2022-09-15 14:01:37,157: ERROR/MainProcess] consumer: Cannot connect to redis://localhost:6379//: Error 111 connecting to localhost:6379. Connection refused..
Trying again in 32.00 seconds... (16/100)

[2022-09-15 14:02:03,527: ERROR/MainProcess] consumer: Cannot connect to redis://localhost:6379//: Error 111 connecting to localhost:6379. Connection refused..
Trying again in 32.00 seconds... (16/100)

[2022-09-15 14:02:09,191: ERROR/MainProcess] consumer: Cannot connect to redis://localhost:6379//: Error 111 connecting to localhost:6379. Connection refused..
Trying again in 32.00 seconds... (16/100)

[2022-09-15 14:02:35,562: ERROR/MainProcess] consumer: Cannot connect to redis://localhost:6379//: Error 111 connecting to localhost:6379. Connection refused..
Trying again in 32.00 seconds... (16/100)

[2022-09-15 14:02:41,226: ERROR/MainProcess] consumer: Cannot connect to redis://localhost:6379//: Error 111 connecting to localhost:6379. Connection refused..
Trying again in 32.00 seconds... (16/100)

[2022-09-15 14:03:07,596: ERROR/MainProcess] consumer: Cannot connect to redis://localhost:6379//: Error 111 connecting to localhost:6379. Connection refused..
Trying again in 32.00 seconds... (16/100)

[2022-09-15 14:03:13,262: ERROR/MainProcess] consumer: Cannot connect to redis://localhost:6379//: Error 111 connecting to localhost:6379. Connection refused..
Trying again in 32.00 seconds... (16/100)

[2022-09-15 14:03:39,631: ERROR/MainProcess] consumer: Cannot connect to redis://localhost:6379//: Error 111 connecting to localhost:6379. Connection refused..
Trying again in 32.00 seconds... (16/100)

[2022-09-15 14:03:45,298: ERROR/MainProcess] consumer: Cannot connect to redis://localhost:6379//: Error 111 connecting to localhost:6379. Connection refused..
Trying again in 32.00 seconds... (16/100)

[2022-09-15 14:04:11,670: ERROR/MainProcess] consumer: Cannot connect to redis://localhost:6379//: Error 111 connecting to localhost:6379. Connection refused..
Trying again in 32.00 seconds... (16/100)

[2022-09-15 14:04:17,333: ERROR/MainProcess] consumer: Cannot connect to redis://localhost:6379//: Error 111 connecting to localhost:6379. Connection refused..
Trying again in 32.00 seconds... (16/100)

[2022-09-15 14:04:43,706: ERROR/MainProcess] consumer: Cannot connect to redis://localhost:6379//: Error 111 connecting to localhost:6379. Connection refused..
Trying again in 32.00 seconds... (16/100)

[2022-09-15 14:04:49,367: ERROR/MainProcess] consumer: Cannot connect to redis://localhost:6379//: Error 111 connecting to localhost:6379. Connection refused..
Trying again in 32.00 seconds... (16/100)

[2022-09-15 14:05:15,743: ERROR/MainProcess] consumer: Cannot connect to redis://localhost:6379//: Error 111 connecting to localhost:6379. Connection refused..
Trying again in 32.00 seconds... (16/100)

[2022-09-15 14:05:21,402: ERROR/MainProcess] consumer: Cannot connect to redis://localhost:6379//: Error 111 connecting to localhost:6379. Connection refused..
Trying again in 32.00 seconds... (16/100)

[2022-09-15 14:05:47,776: ERROR/MainProcess] consumer: Cannot connect to redis://localhost:6379//: Error 111 connecting to localhost:6379. Connection refused..
Trying again in 32.00 seconds... (16/100)

[2022-09-15 14:05:53,437: ERROR/MainProcess] consumer: Cannot connect to redis://localhost:6379//: Error 111 connecting to localhost:6379. Connection refused..
Trying again in 32.00 seconds... (16/100)

[2022-09-15 14:06:19,810: ERROR/MainProcess] consumer: Cannot connect to redis://localhost:6379//: Error 111 connecting to localhost:6379. Connection refused..
Trying again in 32.00 seconds... (16/100)

[2022-09-15 14:06:25,474: ERROR/MainProcess] consumer: Cannot connect to redis://localhost:6379//: Error 111 connecting to localhost:6379. Connection refused..
Trying again in 32.00 seconds... (16/100)

[2022-09-15 14:06:51,844: ERROR/MainProcess] consumer: Cannot connect to redis://localhost:6379//: Error 111 connecting to localhost:6379. Connection refused..
Trying again in 32.00 seconds... (16/100)

[2022-09-15 14:06:57,509: ERROR/MainProcess] consumer: Cannot connect to redis://localhost:6379//: Error 111 connecting to localhost:6379. Connection refused..
Trying again in 32.00 seconds... (16/100)

[2022-09-15 14:07:23,879: ERROR/MainProcess] consumer: Cannot connect to redis://localhost:6379//: Error 111 connecting to localhost:6379. Connection refused..
Trying again in 32.00 seconds... (16/100)

[2022-09-15 14:07:29,545: ERROR/MainProcess] consumer: Cannot connect to redis://localhost:6379//: Error 111 connecting to localhost:6379. Connection refused..
Trying again in 32.00 seconds... (16/100)

[2022-09-15 14:07:55,914: ERROR/MainProcess] consumer: Cannot connect to redis://localhost:6379//: Error 111 connecting to localhost:6379. Connection refused..
Trying again in 32.00 seconds... (16/100)

[2022-09-15 14:08:01,576: ERROR/MainProcess] consumer: Cannot connect to redis://localhost:6379//: Error 111 connecting to localhost:6379. Connection refused..
Trying again in 32.00 seconds... (16/100)

[2022-09-15 14:08:27,950: ERROR/MainProcess] consumer: Cannot connect to redis://localhost:6379//: Error 111 connecting to localhost:6379. Connection refused..
Trying again in 32.00 seconds... (16/100)

[2022-09-15 14:08:44,036: ERROR/MainProcess] consumer: Cannot connect to redis://localhost:6379//: Error 111 connecting to localhost:6379. Connection refused..
Trying again in 2.00 seconds... (1/100)

[2022-09-15 14:08:46,041: ERROR/MainProcess] consumer: Cannot connect to redis://localhost:6379//: Error 111 connecting to localhost:6379. Connection refused..
Trying again in 4.00 seconds... (2/100)

[2022-09-15 14:08:50,048: ERROR/MainProcess] consumer: Cannot connect to redis://localhost:6379//: Error 111 connecting to localhost:6379. Connection refused..
Trying again in 6.00 seconds... (3/100)

[2022-09-15 14:08:56,055: ERROR/MainProcess] consumer: Cannot connect to redis://localhost:6379//: Error 111 connecting to localhost:6379. Connection refused..
Trying again in 8.00 seconds... (4/100)

[2022-09-15 14:08:59,982: ERROR/MainProcess] consumer: Cannot connect to redis://localhost:6379//: Error 111 connecting to localhost:6379. Connection refused..
Trying again in 32.00 seconds... (16/100)

[2022-09-15 14:09:04,064: ERROR/MainProcess] consumer: Cannot connect to redis://localhost:6379//: Error 111 connecting to localhost:6379. Connection refused..
Trying again in 10.00 seconds... (5/100)

[2022-09-15 14:09:14,078: ERROR/MainProcess] consumer: Cannot connect to redis://localhost:6379//: Error 111 connecting to localhost:6379. Connection refused..
Trying again in 12.00 seconds... (6/100)

[2022-09-15 14:09:26,093: ERROR/MainProcess] consumer: Cannot connect to redis://localhost:6379//: Error 111 connecting to localhost:6379. Connection refused..
Trying again in 14.00 seconds... (7/100)

[2022-09-15 14:09:32,018: ERROR/MainProcess] consumer: Cannot connect to redis://localhost:6379//: Error 111 connecting to localhost:6379. Connection refused..
Trying again in 32.00 seconds... (16/100)

[2022-09-15 14:09:40,110: ERROR/MainProcess] consumer: Cannot connect to redis://localhost:6379//: Error 111 connecting to localhost:6379. Connection refused..
Trying again in 16.00 seconds... (8/100)

[2022-09-15 14:09:56,129: ERROR/MainProcess] consumer: Cannot connect to redis://localhost:6379//: Error 111 connecting to localhost:6379. Connection refused..
Trying again in 18.00 seconds... (9/100)

[2022-09-15 14:10:04,052: ERROR/MainProcess] consumer: Cannot connect to redis://localhost:6379//: Error 111 connecting to localhost:6379. Connection refused..
Trying again in 32.00 seconds... (16/100)

[2022-09-15 14:10:14,149: ERROR/MainProcess] consumer: Cannot connect to redis://localhost:6379//: Error 111 connecting to localhost:6379. Connection refused..
Trying again in 20.00 seconds... (10/100)

[2022-09-15 14:10:34,173: ERROR/MainProcess] consumer: Cannot connect to redis://localhost:6379//: Error 111 connecting to localhost:6379. Connection refused..
Trying again in 22.00 seconds... (11/100)

[2022-09-15 14:10:36,087: ERROR/MainProcess] consumer: Cannot connect to redis://localhost:6379//: Error 111 connecting to localhost:6379. Connection refused..
Trying again in 32.00 seconds... (16/100)

[2022-09-15 14:10:56,197: ERROR/MainProcess] consumer: Cannot connect to redis://localhost:6379//: Error 111 connecting to localhost:6379. Connection refused..
Trying again in 24.00 seconds... (12/100)

[2022-09-15 14:11:08,125: ERROR/MainProcess] consumer: Cannot connect to redis://localhost:6379//: Error 111 connecting to localhost:6379. Connection refused..
Trying again in 32.00 seconds... (16/100)

[2022-09-15 14:11:20,224: ERROR/MainProcess] consumer: Cannot connect to redis://localhost:6379//: Error 111 connecting to localhost:6379. Connection refused..
Trying again in 26.00 seconds... (13/100)

[2022-09-15 14:11:40,161: ERROR/MainProcess] consumer: Cannot connect to redis://localhost:6379//: Error 111 connecting to localhost:6379. Connection refused..
Trying again in 32.00 seconds... (16/100)

[2022-09-15 14:11:46,253: ERROR/MainProcess] consumer: Cannot connect to redis://localhost:6379//: Error 111 connecting to localhost:6379. Connection refused..
Trying again in 28.00 seconds... (14/100)

[2022-09-15 14:12:12,195: ERROR/MainProcess] consumer: Cannot connect to redis://localhost:6379//: Error 111 connecting to localhost:6379. Connection refused..
Trying again in 32.00 seconds... (16/100)

[2022-09-15 14:12:14,283: ERROR/MainProcess] consumer: Cannot connect to redis://localhost:6379//: Error 111 connecting to localhost:6379. Connection refused..
Trying again in 30.00 seconds... (15/100)

[2022-09-15 14:12:44,228: ERROR/MainProcess] consumer: Cannot connect to redis://localhost:6379//: Error 111 connecting to localhost:6379. Connection refused..
Trying again in 32.00 seconds... (16/100)

[2022-09-15 14:12:44,314: ERROR/MainProcess] consumer: Cannot connect to redis://localhost:6379//: Error 111 connecting to localhost:6379. Connection refused..
Trying again in 32.00 seconds... (16/100)

[2022-09-15 14:13:16,262: ERROR/MainProcess] consumer: Cannot connect to redis://localhost:6379//: Error 111 connecting to localhost:6379. Connection refused..
Trying again in 32.00 seconds... (16/100)

[2022-09-15 14:13:16,347: ERROR/MainProcess] consumer: Cannot connect to redis://localhost:6379//: Error 111 connecting to localhost:6379. Connection refused..
Trying again in 32.00 seconds... (16/100)

[2022-09-15 14:13:48,297: ERROR/MainProcess] consumer: Cannot connect to redis://localhost:6379//: Error 111 connecting to localhost:6379. Connection refused..
Trying again in 32.00 seconds... (16/100)

[2022-09-15 14:13:48,384: ERROR/MainProcess] consumer: Cannot connect to redis://localhost:6379//: Error 111 connecting to localhost:6379. Connection refused..
Trying again in 32.00 seconds... (16/100)

[2022-09-15 14:14:20,333: ERROR/MainProcess] consumer: Cannot connect to redis://localhost:6379//: Error 111 connecting to localhost:6379. Connection refused..
Trying again in 32.00 seconds... (16/100)

[2022-09-15 14:14:20,419: ERROR/MainProcess] consumer: Cannot connect to redis://localhost:6379//: Error 111 connecting to localhost:6379. Connection refused..
Trying again in 32.00 seconds... (16/100)

[2022-09-15 14:14:52,367: ERROR/MainProcess] consumer: Cannot connect to redis://localhost:6379//: Error 111 connecting to localhost:6379. Connection refused..
Trying again in 32.00 seconds... (16/100)

[2022-09-15 14:14:52,453: ERROR/MainProcess] consumer: Cannot connect to redis://localhost:6379//: Error 111 connecting to localhost:6379. Connection refused..
Trying again in 32.00 seconds... (16/100)

[2022-09-15 14:15:24,401: ERROR/MainProcess] consumer: Cannot connect to redis://localhost:6379//: Error 111 connecting to localhost:6379. Connection refused..
Trying again in 32.00 seconds... (16/100)

[2022-09-15 14:15:24,487: ERROR/MainProcess] consumer: Cannot connect to redis://localhost:6379//: Error 111 connecting to localhost:6379. Connection refused..
Trying again in 32.00 seconds... (16/100)

[2022-09-15 14:15:56,435: ERROR/MainProcess] consumer: Cannot connect to redis://localhost:6379//: Error 111 connecting to localhost:6379. Connection refused..
Trying again in 32.00 seconds... (16/100)

[2022-09-15 14:15:56,519: ERROR/MainProcess] consumer: Cannot connect to redis://localhost:6379//: Error 111 connecting to localhost:6379. Connection refused..
Trying again in 32.00 seconds... (16/100)

[2022-09-15 14:16:28,469: ERROR/MainProcess] consumer: Cannot connect to redis://localhost:6379//: Error 111 connecting to localhost:6379. Connection refused..
Trying again in 32.00 seconds... (16/100)

[2022-09-15 14:16:28,556: ERROR/MainProcess] consumer: Cannot connect to redis://localhost:6379//: Error 111 connecting to localhost:6379. Connection refused..
Trying again in 32.00 seconds... (16/100)

[2022-09-15 14:17:00,506: ERROR/MainProcess] consumer: Cannot connect to redis://localhost:6379//: Error 111 connecting to localhost:6379. Connection refused..
Trying again in 32.00 seconds... (16/100)

[2022-09-15 14:17:00,589: ERROR/MainProcess] consumer: Cannot connect to redis://localhost:6379//: Error 111 connecting to localhost:6379. Connection refused..
Trying again in 32.00 seconds... (16/100)

[2022-09-15 14:17:32,543: ERROR/MainProcess] consumer: Cannot connect to redis://localhost:6379//: Error 111 connecting to localhost:6379. Connection refused..
Trying again in 32.00 seconds... (16/100)

[2022-09-15 14:17:32,625: ERROR/MainProcess] consumer: Cannot connect to redis://localhost:6379//: Error 111 connecting to localhost:6379. Connection refused..
Trying again in 32.00 seconds... (16/100)

[2022-09-15 14:18:04,578: ERROR/MainProcess] consumer: Cannot connect to redis://localhost:6379//: Error 111 connecting to localhost:6379. Connection refused..
Trying again in 32.00 seconds... (16/100)

[2022-09-15 14:18:04,661: ERROR/MainProcess] consumer: Cannot connect to redis://localhost:6379//: Error 111 connecting to localhost:6379. Connection refused..
Trying again in 32.00 seconds... (16/100)

[2022-09-15 14:18:36,612: ERROR/MainProcess] consumer: Cannot connect to redis://localhost:6379//: Error 111 connecting to localhost:6379. Connection refused..
Trying again in 32.00 seconds... (16/100)

[2022-09-15 14:18:36,694: ERROR/MainProcess] consumer: Cannot connect to redis://localhost:6379//: Error 111 connecting to localhost:6379. Connection refused..
Trying again in 32.00 seconds... (16/100)

[2022-09-15 14:19:08,648: ERROR/MainProcess] consumer: Cannot connect to redis://localhost:6379//: Error 111 connecting to localhost:6379. Connection refused..
Trying again in 32.00 seconds... (16/100)

[2022-09-15 14:19:08,728: ERROR/MainProcess] consumer: Cannot connect to redis://localhost:6379//: Error 111 connecting to localhost:6379. Connection refused..
Trying again in 32.00 seconds... (16/100)

[2022-09-15 14:19:40,681: ERROR/MainProcess] consumer: Cannot connect to redis://localhost:6379//: Error 111 connecting to localhost:6379. Connection refused..
Trying again in 32.00 seconds... (16/100)

[2022-09-15 14:19:40,762: ERROR/MainProcess] consumer: Cannot connect to redis://localhost:6379//: Error 111 connecting to localhost:6379. Connection refused..
Trying again in 32.00 seconds... (16/100)

[2022-09-15 14:20:12,716: ERROR/MainProcess] consumer: Cannot connect to redis://localhost:6379//: Error 111 connecting to localhost:6379. Connection refused..
Trying again in 32.00 seconds... (16/100)

[2022-09-15 14:20:12,796: ERROR/MainProcess] consumer: Cannot connect to redis://localhost:6379//: Error 111 connecting to localhost:6379. Connection refused..
Trying again in 32.00 seconds... (16/100)

[2022-09-15 14:20:44,750: ERROR/MainProcess] consumer: Cannot connect to redis://localhost:6379//: Error 111 connecting to localhost:6379. Connection refused..
Trying again in 32.00 seconds... (16/100)

[2022-09-15 14:20:44,831: ERROR/MainProcess] consumer: Cannot connect to redis://localhost:6379//: Error 111 connecting to localhost:6379. Connection refused..
Trying again in 32.00 seconds... (16/100)

[2022-09-15 14:21:16,785: ERROR/MainProcess] consumer: Cannot connect to redis://localhost:6379//: Error 111 connecting to localhost:6379. Connection refused..
Trying again in 32.00 seconds... (16/100)

[2022-09-15 14:21:16,866: ERROR/MainProcess] consumer: Cannot connect to redis://localhost:6379//: Error 111 connecting to localhost:6379. Connection refused..
Trying again in 32.00 seconds... (16/100)

[2022-09-15 14:21:48,817: ERROR/MainProcess] consumer: Cannot connect to redis://localhost:6379//: Error 111 connecting to localhost:6379. Connection refused..
Trying again in 32.00 seconds... (16/100)

[2022-09-15 14:21:48,899: ERROR/MainProcess] consumer: Cannot connect to redis://localhost:6379//: Error 111 connecting to localhost:6379. Connection refused..
Trying again in 32.00 seconds... (16/100)

[2022-09-15 14:22:20,853: ERROR/MainProcess] consumer: Cannot connect to redis://localhost:6379//: Error 111 connecting to localhost:6379. Connection refused..
Trying again in 32.00 seconds... (16/100)

[2022-09-15 14:22:20,934: ERROR/MainProcess] consumer: Cannot connect to redis://localhost:6379//: Error 111 connecting to localhost:6379. Connection refused..
Trying again in 32.00 seconds... (16/100)

[2022-09-15 14:22:52,887: ERROR/MainProcess] consumer: Cannot connect to redis://localhost:6379//: Error 111 connecting to localhost:6379. Connection refused..
Trying again in 32.00 seconds... (16/100)

[2022-09-15 14:22:52,967: ERROR/MainProcess] consumer: Cannot connect to redis://localhost:6379//: Error 111 connecting to localhost:6379. Connection refused..
Trying again in 32.00 seconds... (16/100)

[2022-09-15 14:23:24,921: ERROR/MainProcess] consumer: Cannot connect to redis://localhost:6379//: Error 111 connecting to localhost:6379. Connection refused..
Trying again in 32.00 seconds... (16/100)

[2022-09-15 14:23:25,003: ERROR/MainProcess] consumer: Cannot connect to redis://localhost:6379//: Error 111 connecting to localhost:6379. Connection refused..
Trying again in 32.00 seconds... (16/100)

[2022-09-15 14:23:56,964: INFO/MainProcess] Connected to redis://localhost:6379//
[2022-09-15 14:23:56,970: INFO/MainProcess] mingle: searching for neighbors
[2022-09-15 14:23:57,044: INFO/MainProcess] Connected to redis://localhost:6379//
[2022-09-15 14:23:57,056: INFO/MainProcess] mingle: searching for neighbors
[2022-09-15 14:23:57,989: INFO/MainProcess] mingle: all alone
[2022-09-15 14:23:58,000: WARNING/MainProcess] /run/media/pirate/STORAGE/System-Application/anaconda3/envs/Django_env/lib/python3.10/site-packages/celery/fixups/django.py:203: UserWarning: Using settings.DEBUG leads to a memory
            leak, never use this setting in production environments!
  warnings.warn('''Using settings.DEBUG leads to a memory

[2022-09-15 14:23:58,000: INFO/MainProcess] celery@Asteria ready.
[2022-09-15 14:23:58,072: INFO/MainProcess] mingle: all alone
[2022-09-15 14:23:58,087: WARNING/MainProcess] /run/media/pirate/STORAGE/System-Application/anaconda3/envs/Django_env/lib/python3.10/site-packages/celery/fixups/django.py:203: UserWarning: Using settings.DEBUG leads to a memory
            leak, never use this setting in production environments!
  warnings.warn('''Using settings.DEBUG leads to a memory

[2022-09-15 14:23:58,087: INFO/MainProcess] celery@Asteria ready.
[2022-09-15 14:26:12,778: ERROR/MainProcess] Received unregistered task of type 'services.tasks.start_web_scraping_linkedin'.
The message has been ignored and discarded.

Did you remember to import the module containing this task?
Or maybe you're using relative imports?

Please see
http://docs.celeryq.org/en/latest/internals/protocol.html
for more information.

The full contents of the message body was:
b'[[], {}, {"callbacks": null, "errbacks": null, "chain": null, "chord": null}]' (77b)

Thw full contents of the message headers:
{'lang': 'py', 'task': 'services.tasks.start_web_scraping_linkedin', 'id': '727023b3-c643-4235-800d-943eba29ddee', 'shadow': None, 'eta': None, 'expires': None, 'group': None, 'group_index': None, 'retries': 0, 'timelimit': [None, None], 'root_id': '727023b3-c643-4235-800d-943eba29ddee', 'parent_id': None, 'argsrepr': '()', 'kwargsrepr': '{}', 'origin': 'gen109188@Asteria', 'ignore_result': False}

The delivery info for this task is:
{'exchange': '', 'routing_key': 'celery'}
Traceback (most recent call last):
  File "/run/media/pirate/STORAGE/System-Application/anaconda3/envs/Django_env/lib/python3.10/site-packages/celery/worker/consumer/consumer.py", line 591, in on_task_received
    strategy = strategies[type_]
KeyError: 'services.tasks.start_web_scraping_linkedin'
[2022-09-15 20:06:57,810: INFO/MainProcess] Connected to redis://localhost:6379//
[2022-09-15 20:06:57,813: INFO/MainProcess] mingle: searching for neighbors
[2022-09-15 20:06:58,824: INFO/MainProcess] mingle: all alone
[2022-09-15 20:06:58,853: WARNING/MainProcess] /run/media/pirate/STORAGE/System-Application/anaconda3/envs/Django_env/lib/python3.10/site-packages/celery/fixups/django.py:203: UserWarning: Using settings.DEBUG leads to a memory
            leak, never use this setting in production environments!
  warnings.warn('''Using settings.DEBUG leads to a memory

[2022-09-15 20:06:58,853: INFO/MainProcess] celery@Asteria ready.
[2022-09-15 20:08:15,249: INFO/MainProcess] Task services.tasks.start_web_scraping_linkedin[a02a0635-f6a3-42c5-a555-43db87d940ca] received
[2022-09-15 20:08:15,888: INFO/ForkPoolWorker-7] Task services.tasks.start_web_scraping_linkedin[a02a0635-f6a3-42c5-a555-43db87d940ca] succeeded in 0.6375989770021988s: None
[2022-09-15 20:13:17,690: INFO/MainProcess] Task services.tasks.start_web_scraping_linkedin[35be3ee6-3777-48ee-9c12-63f1752e6ea8] received
[2022-09-15 20:13:27,721: ERROR/ForkPoolWorker-7] Error in getting link Job() got an unexpected keyword argument 'requirement'
[2022-09-15 20:13:27,722: INFO/ForkPoolWorker-7] Task services.tasks.start_web_scraping_linkedin[35be3ee6-3777-48ee-9c12-63f1752e6ea8] succeeded in 10.027993876003165s: None


[2022-09-15 20:22:17,378: INFO/MainProcess] Connected to redis://localhost:6379//
[2022-09-15 20:22:17,381: INFO/MainProcess] mingle: searching for neighbors
[2022-09-15 20:22:18,392: INFO/MainProcess] mingle: all alone
[2022-09-15 20:22:18,424: WARNING/MainProcess] /run/media/pirate/STORAGE/System-Application/anaconda3/envs/Django_env/lib/python3.10/site-packages/celery/fixups/django.py:203: UserWarning: Using settings.DEBUG leads to a memory
            leak, never use this setting in production environments!
  warnings.warn('''Using settings.DEBUG leads to a memory

[2022-09-15 20:22:18,424: INFO/MainProcess] celery@Asteria ready.
[2022-09-15 20:22:18,429: INFO/MainProcess] Task services.tasks.start_web_scraping_linkedin[c9b365d1-97b8-435b-b183-bacce770faec] received
[2022-09-15 20:22:26,401: INFO/ForkPoolWorker-7] 21 Data Analyst has been added to the database
[2022-09-15 20:22:27,035: INFO/MainProcess] Task services.tasks.start_web_scraping_linkedin[36c17bfc-fb07-4afa-8858-17b6afe1562e] received
[2022-09-15 20:22:28,770: INFO/ForkPoolWorker-7] 22 Business Presentation Specialist (Trainee) has been added to the database
[2022-09-15 20:22:31,555: INFO/ForkPoolWorker-8] 23 Data Analyst has been added to the database
[2022-09-15 20:22:31,694: INFO/ForkPoolWorker-7] 24 Junior Solution Delivery Analyst - Ignite has been added to the database
[2022-09-15 20:22:34,355: INFO/ForkPoolWorker-8] 25 Business Presentation Specialist (Trainee) has been added to the database
[2022-09-15 20:22:34,834: INFO/ForkPoolWorker-7] 26 Data Analyst - Orpheus has been added to the database
[2022-09-15 20:22:36,375: INFO/ForkPoolWorker-7] 27 Business Presentation Specialist (Trainee) has been added to the database
[2022-09-15 20:22:37,904: INFO/ForkPoolWorker-7] 28 Knowledge Analyst - Private Equity & Principal Investors has been added to the database
[2022-09-15 20:22:38,961: INFO/ForkPoolWorker-8] 29 Executive Assistant has been added to the database
[2022-09-15 20:22:39,431: INFO/ForkPoolWorker-7] 30 Executive Assistant has been added to the database
[2022-09-15 20:22:41,169: INFO/ForkPoolWorker-8] 31 Business Presentation Specialist (Trainee) has been added to the database
[2022-09-15 20:22:41,396: INFO/ForkPoolWorker-7] 32 Junior Capabilities and Insights Analyst - People and Organizational Performance has been added to the database
[2022-09-15 20:22:43,662: INFO/ForkPoolWorker-8] 33 Office Services Coordinator has been added to the database
[2022-09-15 20:22:43,859: INFO/ForkPoolWorker-7] 34 Office Services Coordinator has been added to the database
[2022-09-15 20:22:45,399: INFO/ForkPoolWorker-8] 35 Data Analyst - Orpheus has been added to the database
[2022-09-15 20:22:45,540: INFO/ForkPoolWorker-7] 36 Project Finance Controller has been added to the database
[2022-09-15 20:22:48,434: INFO/ForkPoolWorker-7] 37 Analyst – OrgSolutions has been added to the database
[2022-09-15 20:22:48,611: INFO/ForkPoolWorker-8] 38 Project Finance Controller has been added to the database
[2022-09-15 20:22:49,908: INFO/ForkPoolWorker-7] 39 Capabilities and Insights Analyst_Corporate and Invest Banking_Gurugram has been added to the database
[2022-09-15 20:22:50,148: INFO/ForkPoolWorker-8] 40 Junior Capabilities and Insights Analyst - People and Organizational Performance has been added to the database
[2022-09-15 20:22:51,348: INFO/ForkPoolWorker-7] 41 Research Science Analyst_Global Payments Map_Gurugram has been added to the database
[2022-09-15 20:22:52,602: INFO/ForkPoolWorker-8] 42 Junior Solution Delivery Analyst - Ignite has been added to the database
[2022-09-15 20:22:55,451: INFO/ForkPoolWorker-8] 43 Receptionist has been added to the database
[2022-09-15 20:22:55,614: INFO/ForkPoolWorker-7] 44 Investment Operations Manager and Trust Associate has been added to the database
[2022-09-15 20:22:56,933: INFO/ForkPoolWorker-8] 45 Knowledge Analyst - Private Equity & Principal Investors has been added to the database
[2022-09-15 20:22:58,441: INFO/ForkPoolWorker-7] 46 Solution Delivery Analyst has been added to the database
[2022-09-15 20:22:58,540: INFO/ForkPoolWorker-8] 47 Engagement Manager - Procurement has been added to the database
[2022-09-15 20:22:59,937: INFO/ForkPoolWorker-7] 48 Capabilities & Insights Analyst - People and Organizational Performance has been added to the database
[2022-09-15 20:23:00,290: INFO/ForkPoolWorker-8] 49 Analyst – OrgSolutions has been added to the database
[2022-09-15 20:23:00,845: ERROR/ForkPoolWorker-7] Error in getting link 'NoneType' object has no attribute 'text'
[2022-09-15 20:23:00,846: INFO/ForkPoolWorker-7] Task services.tasks.start_web_scraping_linkedin[c9b365d1-97b8-435b-b183-bacce770faec] succeeded in 42.41545893699731s: None
[2022-09-15 20:23:02,555: INFO/ForkPoolWorker-8] 50 Research Science Analyst - Panorama Financial Institutions Center has been added to the database
[2022-09-15 20:23:04,039: INFO/ForkPoolWorker-8] 51 Investment Operations Manager and Trust Associate has been added to the database
[2022-09-15 20:23:07,488: INFO/ForkPoolWorker-8] 52 Capabilities & Insights Analyst - People and Organizational Performance has been added to the database
[2022-09-15 20:23:09,247: INFO/ForkPoolWorker-8] 53 Professional Development Manager – McKinsey Digital (Build Hub) has been added to the database
[2022-09-15 20:23:10,175: ERROR/ForkPoolWorker-8] Error in getting link 'NoneType' object has no attribute 'text'
[2022-09-15 20:23:10,180: INFO/ForkPoolWorker-8] Task services.tasks.start_web_scraping_linkedin[36c17bfc-fb07-4afa-8858-17b6afe1562e] succeeded in 43.1425727379974s: None
[2022-09-20 21:07:54,534: ERROR/MainProcess] consumer: Cannot connect to redis://localhost:6379//: Error 111 connecting to localhost:6379. Connection refused..
Trying again in 2.00 seconds... (1/100)

[2022-09-20 21:07:56,562: ERROR/MainProcess] consumer: Cannot connect to redis://localhost:6379//: Error 111 connecting to localhost:6379. Connection refused..
Trying again in 4.00 seconds... (2/100)

[2022-09-20 21:08:00,569: ERROR/MainProcess] consumer: Cannot connect to redis://localhost:6379//: Error 111 connecting to localhost:6379. Connection refused..
Trying again in 6.00 seconds... (3/100)

[2022-09-20 21:08:06,578: ERROR/MainProcess] consumer: Cannot connect to redis://localhost:6379//: Error 111 connecting to localhost:6379. Connection refused..
Trying again in 8.00 seconds... (4/100)

[2022-09-20 21:08:14,588: ERROR/MainProcess] consumer: Cannot connect to redis://localhost:6379//: Error 111 connecting to localhost:6379. Connection refused..
Trying again in 10.00 seconds... (5/100)

[2022-09-20 21:08:24,602: ERROR/MainProcess] consumer: Cannot connect to redis://localhost:6379//: Error 111 connecting to localhost:6379. Connection refused..
Trying again in 12.00 seconds... (6/100)

[2022-09-20 21:08:36,617: ERROR/MainProcess] consumer: Cannot connect to redis://localhost:6379//: Error 111 connecting to localhost:6379. Connection refused..
Trying again in 14.00 seconds... (7/100)

[2022-09-20 21:08:50,634: ERROR/MainProcess] consumer: Cannot connect to redis://localhost:6379//: Error 111 connecting to localhost:6379. Connection refused..
Trying again in 16.00 seconds... (8/100)

[2022-09-20 21:09:06,651: ERROR/MainProcess] consumer: Cannot connect to redis://localhost:6379//: Error 111 connecting to localhost:6379. Connection refused..
Trying again in 18.00 seconds... (9/100)

[2022-09-20 21:09:24,673: ERROR/MainProcess] consumer: Cannot connect to redis://localhost:6379//: Error 111 connecting to localhost:6379. Connection refused..
Trying again in 20.00 seconds... (10/100)

[2022-09-20 21:09:44,696: ERROR/MainProcess] consumer: Cannot connect to redis://localhost:6379//: Error 111 connecting to localhost:6379. Connection refused..
Trying again in 22.00 seconds... (11/100)

[2022-09-20 21:10:06,721: ERROR/MainProcess] consumer: Cannot connect to redis://localhost:6379//: Error 111 connecting to localhost:6379. Connection refused..
Trying again in 24.00 seconds... (12/100)

[2022-09-20 21:10:30,745: ERROR/MainProcess] consumer: Cannot connect to redis://localhost:6379//: Error 111 connecting to localhost:6379. Connection refused..
Trying again in 26.00 seconds... (13/100)

[2022-09-20 21:10:56,774: ERROR/MainProcess] consumer: Cannot connect to redis://localhost:6379//: Error 111 connecting to localhost:6379. Connection refused..
Trying again in 28.00 seconds... (14/100)

[2022-09-20 21:11:24,803: ERROR/MainProcess] consumer: Cannot connect to redis://localhost:6379//: Error 111 connecting to localhost:6379. Connection refused..
Trying again in 30.00 seconds... (15/100)

[2022-09-20 21:11:54,837: ERROR/MainProcess] consumer: Cannot connect to redis://localhost:6379//: Error 111 connecting to localhost:6379. Connection refused..
Trying again in 32.00 seconds... (16/100)

[2022-09-20 21:12:26,874: ERROR/MainProcess] consumer: Cannot connect to redis://localhost:6379//: Error 111 connecting to localhost:6379. Connection refused..
Trying again in 32.00 seconds... (16/100)

[2022-09-20 21:12:58,909: ERROR/MainProcess] consumer: Cannot connect to redis://localhost:6379//: Error 111 connecting to localhost:6379. Connection refused..
Trying again in 32.00 seconds... (16/100)

[2022-09-20 21:13:30,943: ERROR/MainProcess] consumer: Cannot connect to redis://localhost:6379//: Error 111 connecting to localhost:6379. Connection refused..
Trying again in 32.00 seconds... (16/100)

[2022-09-20 21:14:02,980: ERROR/MainProcess] consumer: Cannot connect to redis://localhost:6379//: Error 111 connecting to localhost:6379. Connection refused..
Trying again in 32.00 seconds... (16/100)

[2022-09-20 21:14:35,015: ERROR/MainProcess] consumer: Cannot connect to redis://localhost:6379//: Error 111 connecting to localhost:6379. Connection refused..
Trying again in 32.00 seconds... (16/100)

[2022-09-20 21:15:07,048: ERROR/MainProcess] consumer: Cannot connect to redis://localhost:6379//: Error 111 connecting to localhost:6379. Connection refused..
Trying again in 32.00 seconds... (16/100)

[2022-09-20 21:15:39,084: ERROR/MainProcess] consumer: Cannot connect to redis://localhost:6379//: Error 111 connecting to localhost:6379. Connection refused..
Trying again in 32.00 seconds... (16/100)

[2022-09-20 21:16:11,118: ERROR/MainProcess] consumer: Cannot connect to redis://localhost:6379//: Error 111 connecting to localhost:6379. Connection refused..
Trying again in 32.00 seconds... (16/100)

[2022-09-20 21:16:43,155: ERROR/MainProcess] consumer: Cannot connect to redis://localhost:6379//: Error 111 connecting to localhost:6379. Connection refused..
Trying again in 32.00 seconds... (16/100)

[2022-09-20 21:17:15,191: ERROR/MainProcess] consumer: Cannot connect to redis://localhost:6379//: Error 111 connecting to localhost:6379. Connection refused..
Trying again in 32.00 seconds... (16/100)

[2022-09-20 21:17:47,226: ERROR/MainProcess] consumer: Cannot connect to redis://localhost:6379//: Error 111 connecting to localhost:6379. Connection refused..
Trying again in 32.00 seconds... (16/100)

[2022-09-20 21:18:19,261: ERROR/MainProcess] consumer: Cannot connect to redis://localhost:6379//: Error 111 connecting to localhost:6379. Connection refused..
Trying again in 32.00 seconds... (16/100)

[2022-09-20 21:18:51,294: ERROR/MainProcess] consumer: Cannot connect to redis://localhost:6379//: Error 111 connecting to localhost:6379. Connection refused..
Trying again in 32.00 seconds... (16/100)

[2022-09-20 21:19:23,330: ERROR/MainProcess] consumer: Cannot connect to redis://localhost:6379//: Error 111 connecting to localhost:6379. Connection refused..
Trying again in 32.00 seconds... (16/100)

[2022-09-20 21:19:55,365: ERROR/MainProcess] consumer: Cannot connect to redis://localhost:6379//: Error 111 connecting to localhost:6379. Connection refused..
Trying again in 32.00 seconds... (16/100)

[2022-09-20 21:20:27,400: ERROR/MainProcess] consumer: Cannot connect to redis://localhost:6379//: Error 111 connecting to localhost:6379. Connection refused..
Trying again in 32.00 seconds... (16/100)

[2022-09-20 21:20:59,432: ERROR/MainProcess] consumer: Cannot connect to redis://localhost:6379//: Error 111 connecting to localhost:6379. Connection refused..
Trying again in 32.00 seconds... (16/100)

[2022-09-20 21:21:31,469: ERROR/MainProcess] consumer: Cannot connect to redis://localhost:6379//: Error 111 connecting to localhost:6379. Connection refused..
Trying again in 32.00 seconds... (16/100)

[2022-09-20 21:22:03,502: ERROR/MainProcess] consumer: Cannot connect to redis://localhost:6379//: Error 111 connecting to localhost:6379. Connection refused..
Trying again in 32.00 seconds... (16/100)

[2022-09-20 21:22:35,537: ERROR/MainProcess] consumer: Cannot connect to redis://localhost:6379//: Error 111 connecting to localhost:6379. Connection refused..
Trying again in 32.00 seconds... (16/100)

[2022-09-20 21:23:07,572: ERROR/MainProcess] consumer: Cannot connect to redis://localhost:6379//: Error 111 connecting to localhost:6379. Connection refused..
Trying again in 32.00 seconds... (16/100)

[2022-09-20 21:23:39,608: ERROR/MainProcess] consumer: Cannot connect to redis://localhost:6379//: Error 111 connecting to localhost:6379. Connection refused..
Trying again in 32.00 seconds... (16/100)

[2022-09-20 21:24:11,643: ERROR/MainProcess] consumer: Cannot connect to redis://localhost:6379//: Error 111 connecting to localhost:6379. Connection refused..
Trying again in 32.00 seconds... (16/100)

[2022-09-20 21:24:43,678: ERROR/MainProcess] consumer: Cannot connect to redis://localhost:6379//: Error 111 connecting to localhost:6379. Connection refused..
Trying again in 32.00 seconds... (16/100)

[2022-09-20 21:25:15,713: ERROR/MainProcess] consumer: Cannot connect to redis://localhost:6379//: Error 111 connecting to localhost:6379. Connection refused..
Trying again in 32.00 seconds... (16/100)

[2022-09-20 21:25:47,747: ERROR/MainProcess] consumer: Cannot connect to redis://localhost:6379//: Error 111 connecting to localhost:6379. Connection refused..
Trying again in 32.00 seconds... (16/100)

[2022-09-20 21:26:19,785: ERROR/MainProcess] consumer: Cannot connect to redis://localhost:6379//: Error 111 connecting to localhost:6379. Connection refused..
Trying again in 32.00 seconds... (16/100)

[2022-09-20 21:26:51,822: ERROR/MainProcess] consumer: Cannot connect to redis://localhost:6379//: Error 111 connecting to localhost:6379. Connection refused..
Trying again in 32.00 seconds... (16/100)

[2022-09-20 21:27:23,858: ERROR/MainProcess] consumer: Cannot connect to redis://localhost:6379//: Error 111 connecting to localhost:6379. Connection refused..
Trying again in 32.00 seconds... (16/100)

[2022-09-20 21:27:55,893: ERROR/MainProcess] consumer: Cannot connect to redis://localhost:6379//: Error 111 connecting to localhost:6379. Connection refused..
Trying again in 32.00 seconds... (16/100)

[2022-09-20 21:28:27,928: ERROR/MainProcess] consumer: Cannot connect to redis://localhost:6379//: Error 111 connecting to localhost:6379. Connection refused..
Trying again in 32.00 seconds... (16/100)

[2022-09-20 21:28:59,963: ERROR/MainProcess] consumer: Cannot connect to redis://localhost:6379//: Error 111 connecting to localhost:6379. Connection refused..
Trying again in 32.00 seconds... (16/100)

[2022-09-20 21:29:31,999: ERROR/MainProcess] consumer: Cannot connect to redis://localhost:6379//: Error 111 connecting to localhost:6379. Connection refused..
Trying again in 32.00 seconds... (16/100)

[2022-09-20 21:30:04,034: ERROR/MainProcess] consumer: Cannot connect to redis://localhost:6379//: Error 111 connecting to localhost:6379. Connection refused..
Trying again in 32.00 seconds... (16/100)

[2022-09-20 21:30:36,070: ERROR/MainProcess] consumer: Cannot connect to redis://localhost:6379//: Error 111 connecting to localhost:6379. Connection refused..
Trying again in 32.00 seconds... (16/100)

[2022-09-20 21:31:08,103: ERROR/MainProcess] consumer: Cannot connect to redis://localhost:6379//: Error 111 connecting to localhost:6379. Connection refused..
Trying again in 32.00 seconds... (16/100)

[2022-09-20 21:31:40,139: ERROR/MainProcess] consumer: Cannot connect to redis://localhost:6379//: Error 111 connecting to localhost:6379. Connection refused..
Trying again in 32.00 seconds... (16/100)

[2022-09-20 21:32:12,171: ERROR/MainProcess] consumer: Cannot connect to redis://localhost:6379//: Error 111 connecting to localhost:6379. Connection refused..
Trying again in 32.00 seconds... (16/100)

[2022-09-20 21:32:44,207: ERROR/MainProcess] consumer: Cannot connect to redis://localhost:6379//: Error 111 connecting to localhost:6379. Connection refused..
Trying again in 32.00 seconds... (16/100)

[2022-09-20 21:33:16,243: ERROR/MainProcess] consumer: Cannot connect to redis://localhost:6379//: Error 111 connecting to localhost:6379. Connection refused..
Trying again in 32.00 seconds... (16/100)

[2022-09-20 21:33:48,279: ERROR/MainProcess] consumer: Cannot connect to redis://localhost:6379//: Error 111 connecting to localhost:6379. Connection refused..
Trying again in 32.00 seconds... (16/100)

[2022-09-20 21:34:20,314: ERROR/MainProcess] consumer: Cannot connect to redis://localhost:6379//: Error 111 connecting to localhost:6379. Connection refused..
Trying again in 32.00 seconds... (16/100)

[2022-09-20 21:34:52,350: ERROR/MainProcess] consumer: Cannot connect to redis://localhost:6379//: Error 111 connecting to localhost:6379. Connection refused..
Trying again in 32.00 seconds... (16/100)

[2022-09-20 21:35:24,385: ERROR/MainProcess] consumer: Cannot connect to redis://localhost:6379//: Error 111 connecting to localhost:6379. Connection refused..
Trying again in 32.00 seconds... (16/100)

[2022-09-20 21:35:56,419: ERROR/MainProcess] consumer: Cannot connect to redis://localhost:6379//: Error 111 connecting to localhost:6379. Connection refused..
Trying again in 32.00 seconds... (16/100)

[2022-09-20 21:36:28,455: ERROR/MainProcess] consumer: Cannot connect to redis://localhost:6379//: Error 111 connecting to localhost:6379. Connection refused..
Trying again in 32.00 seconds... (16/100)

[2022-09-20 21:37:00,489: ERROR/MainProcess] consumer: Cannot connect to redis://localhost:6379//: Error 111 connecting to localhost:6379. Connection refused..
Trying again in 32.00 seconds... (16/100)

[2022-09-20 21:37:32,522: ERROR/MainProcess] consumer: Cannot connect to redis://localhost:6379//: Error 111 connecting to localhost:6379. Connection refused..
Trying again in 32.00 seconds... (16/100)

[2022-09-20 21:38:04,556: ERROR/MainProcess] consumer: Cannot connect to redis://localhost:6379//: Error 111 connecting to localhost:6379. Connection refused..
Trying again in 32.00 seconds... (16/100)

[2022-09-20 21:38:36,592: ERROR/MainProcess] consumer: Cannot connect to redis://localhost:6379//: Error 111 connecting to localhost:6379. Connection refused..
Trying again in 32.00 seconds... (16/100)

[2022-09-20 21:39:08,631: ERROR/MainProcess] consumer: Cannot connect to redis://localhost:6379//: Error 111 connecting to localhost:6379. Connection refused..
Trying again in 32.00 seconds... (16/100)

[2022-09-20 21:39:40,667: ERROR/MainProcess] consumer: Cannot connect to redis://localhost:6379//: Error 111 connecting to localhost:6379. Connection refused..
Trying again in 32.00 seconds... (16/100)

[2022-09-20 21:40:12,703: ERROR/MainProcess] consumer: Cannot connect to redis://localhost:6379//: Error 111 connecting to localhost:6379. Connection refused..
Trying again in 32.00 seconds... (16/100)

[2022-09-20 21:40:44,737: ERROR/MainProcess] consumer: Cannot connect to redis://localhost:6379//: Error 111 connecting to localhost:6379. Connection refused..
Trying again in 32.00 seconds... (16/100)

[2022-09-20 21:41:16,771: ERROR/MainProcess] consumer: Cannot connect to redis://localhost:6379//: Error 111 connecting to localhost:6379. Connection refused..
Trying again in 32.00 seconds... (16/100)

[2022-09-20 21:41:48,805: ERROR/MainProcess] consumer: Cannot connect to redis://localhost:6379//: Error 111 connecting to localhost:6379. Connection refused..
Trying again in 32.00 seconds... (16/100)

[2022-09-20 21:42:20,842: ERROR/MainProcess] consumer: Cannot connect to redis://localhost:6379//: Error 111 connecting to localhost:6379. Connection refused..
Trying again in 32.00 seconds... (16/100)

[2022-09-20 21:42:52,875: ERROR/MainProcess] consumer: Cannot connect to redis://localhost:6379//: Error 111 connecting to localhost:6379. Connection refused..
Trying again in 32.00 seconds... (16/100)

[2022-09-20 21:43:24,908: ERROR/MainProcess] consumer: Cannot connect to redis://localhost:6379//: Error 111 connecting to localhost:6379. Connection refused..
Trying again in 32.00 seconds... (16/100)

[2022-09-20 21:43:56,941: ERROR/MainProcess] consumer: Cannot connect to redis://localhost:6379//: Error 111 connecting to localhost:6379. Connection refused..
Trying again in 32.00 seconds... (16/100)

[2022-09-20 21:44:28,973: ERROR/MainProcess] consumer: Cannot connect to redis://localhost:6379//: Error 111 connecting to localhost:6379. Connection refused..
Trying again in 32.00 seconds... (16/100)

[2022-09-20 21:45:01,008: ERROR/MainProcess] consumer: Cannot connect to redis://localhost:6379//: Error 111 connecting to localhost:6379. Connection refused..
Trying again in 32.00 seconds... (16/100)

[2022-09-20 21:45:33,040: ERROR/MainProcess] consumer: Cannot connect to redis://localhost:6379//: Error 111 connecting to localhost:6379. Connection refused..
Trying again in 32.00 seconds... (16/100)

[2022-09-20 21:46:05,075: ERROR/MainProcess] consumer: Cannot connect to redis://localhost:6379//: Error 111 connecting to localhost:6379. Connection refused..
Trying again in 32.00 seconds... (16/100)

[2022-09-20 21:46:37,109: ERROR/MainProcess] consumer: Cannot connect to redis://localhost:6379//: Error 111 connecting to localhost:6379. Connection refused..
Trying again in 32.00 seconds... (16/100)

[2022-09-20 21:47:09,145: ERROR/MainProcess] consumer: Cannot connect to redis://localhost:6379//: Error 111 connecting to localhost:6379. Connection refused..
Trying again in 32.00 seconds... (16/100)

[2022-09-20 21:47:41,181: ERROR/MainProcess] consumer: Cannot connect to redis://localhost:6379//: Error 111 connecting to localhost:6379. Connection refused..
Trying again in 32.00 seconds... (16/100)

[2022-09-20 21:48:13,217: ERROR/MainProcess] consumer: Cannot connect to redis://localhost:6379//: Error 111 connecting to localhost:6379. Connection refused..
Trying again in 32.00 seconds... (16/100)

[2022-09-20 21:48:45,253: ERROR/MainProcess] consumer: Cannot connect to redis://localhost:6379//: Error 111 connecting to localhost:6379. Connection refused..
Trying again in 32.00 seconds... (16/100)

[2022-09-20 21:49:17,288: ERROR/MainProcess] consumer: Cannot connect to redis://localhost:6379//: Error 111 connecting to localhost:6379. Connection refused..
Trying again in 32.00 seconds... (16/100)

[2022-09-20 21:49:49,324: ERROR/MainProcess] consumer: Cannot connect to redis://localhost:6379//: Error 111 connecting to localhost:6379. Connection refused..
Trying again in 32.00 seconds... (16/100)

[2022-09-20 21:50:21,360: ERROR/MainProcess] consumer: Cannot connect to redis://localhost:6379//: Error 111 connecting to localhost:6379. Connection refused..
Trying again in 32.00 seconds... (16/100)

[2022-09-20 21:50:53,397: ERROR/MainProcess] consumer: Cannot connect to redis://localhost:6379//: Error 111 connecting to localhost:6379. Connection refused..
Trying again in 32.00 seconds... (16/100)

[2022-09-20 21:51:25,433: ERROR/MainProcess] consumer: Cannot connect to redis://localhost:6379//: Error 111 connecting to localhost:6379. Connection refused..
Trying again in 32.00 seconds... (16/100)

[2022-09-20 21:51:57,469: ERROR/MainProcess] consumer: Cannot connect to redis://localhost:6379//: Error 111 connecting to localhost:6379. Connection refused..
Trying again in 32.00 seconds... (16/100)

[2022-09-20 21:52:29,503: ERROR/MainProcess] consumer: Cannot connect to redis://localhost:6379//: Error 111 connecting to localhost:6379. Connection refused..
Trying again in 32.00 seconds... (16/100)

[2022-09-20 21:53:01,539: ERROR/MainProcess] consumer: Cannot connect to redis://localhost:6379//: Error 111 connecting to localhost:6379. Connection refused..
Trying again in 32.00 seconds... (16/100)

[2022-09-20 21:53:33,575: ERROR/MainProcess] consumer: Cannot connect to redis://localhost:6379//: Error 111 connecting to localhost:6379. Connection refused..
Trying again in 32.00 seconds... (16/100)

[2022-09-20 21:54:05,610: ERROR/MainProcess] consumer: Cannot connect to redis://localhost:6379//: Error 111 connecting to localhost:6379. Connection refused..
Trying again in 32.00 seconds... (16/100)

[2022-09-20 21:54:37,642: ERROR/MainProcess] consumer: Cannot connect to redis://localhost:6379//: Error 111 connecting to localhost:6379. Connection refused..
Trying again in 32.00 seconds... (16/100)

[2022-09-20 21:55:09,677: ERROR/MainProcess] consumer: Cannot connect to redis://localhost:6379//: Error 111 connecting to localhost:6379. Connection refused..
Trying again in 32.00 seconds... (16/100)

[2022-09-20 21:55:41,711: ERROR/MainProcess] consumer: Cannot connect to redis://localhost:6379//: Error 111 connecting to localhost:6379. Connection refused..
Trying again in 32.00 seconds... (16/100)

[2022-09-20 21:56:13,744: ERROR/MainProcess] consumer: Cannot connect to redis://localhost:6379//: Error 111 connecting to localhost:6379. Connection refused..
Trying again in 32.00 seconds... (16/100)

[2022-09-20 21:56:45,778: ERROR/MainProcess] consumer: Cannot connect to redis://localhost:6379//: Error 111 connecting to localhost:6379. Connection refused..
Trying again in 32.00 seconds... (16/100)

[2022-09-20 21:57:17,817: CRITICAL/MainProcess] Unrecoverable error: OperationalError('Error 111 connecting to localhost:6379. Connection refused.')
Traceback (most recent call last):
  File "/run/media/pirate/STORAGE/System-Application/anaconda3/envs/Django_env/lib/python3.10/site-packages/kombu/transport/virtual/base.py", line 925, in create_channel
    return self._avail_channels.pop()
IndexError: pop from empty list

During handling of the above exception, another exception occurred:

Traceback (most recent call last):
  File "/run/media/pirate/STORAGE/System-Application/anaconda3/envs/Django_env/lib/python3.10/site-packages/redis/connection.py", line 611, in connect
    sock = self.retry.call_with_retry(
  File "/run/media/pirate/STORAGE/System-Application/anaconda3/envs/Django_env/lib/python3.10/site-packages/redis/retry.py", line 46, in call_with_retry
    return do()
  File "/run/media/pirate/STORAGE/System-Application/anaconda3/envs/Django_env/lib/python3.10/site-packages/redis/connection.py", line 612, in <lambda>
    lambda: self._connect(), lambda error: self.disconnect(error)
  File "/run/media/pirate/STORAGE/System-Application/anaconda3/envs/Django_env/lib/python3.10/site-packages/redis/connection.py", line 677, in _connect
    raise err
  File "/run/media/pirate/STORAGE/System-Application/anaconda3/envs/Django_env/lib/python3.10/site-packages/redis/connection.py", line 665, in _connect
    sock.connect(socket_address)
ConnectionRefusedError: [Errno 111] Connection refused

During handling of the above exception, another exception occurred:

Traceback (most recent call last):
  File "/run/media/pirate/STORAGE/System-Application/anaconda3/envs/Django_env/lib/python3.10/site-packages/kombu/connection.py", line 446, in _reraise_as_library_errors
    yield
  File "/run/media/pirate/STORAGE/System-Application/anaconda3/envs/Django_env/lib/python3.10/site-packages/kombu/connection.py", line 433, in _ensure_connection
    return retry_over_time(
  File "/run/media/pirate/STORAGE/System-Application/anaconda3/envs/Django_env/lib/python3.10/site-packages/kombu/utils/functional.py", line 312, in retry_over_time
    return fun(*args, **kwargs)
  File "/run/media/pirate/STORAGE/System-Application/anaconda3/envs/Django_env/lib/python3.10/site-packages/kombu/connection.py", line 877, in _connection_factory
    self._connection = self._establish_connection()
  File "/run/media/pirate/STORAGE/System-Application/anaconda3/envs/Django_env/lib/python3.10/site-packages/kombu/connection.py", line 812, in _establish_connection
    conn = self.transport.establish_connection()
  File "/run/media/pirate/STORAGE/System-Application/anaconda3/envs/Django_env/lib/python3.10/site-packages/kombu/transport/virtual/base.py", line 949, in establish_connection
    self._avail_channels.append(self.create_channel(self))
  File "/run/media/pirate/STORAGE/System-Application/anaconda3/envs/Django_env/lib/python3.10/site-packages/kombu/transport/virtual/base.py", line 927, in create_channel
    channel = self.Channel(connection)
  File "/run/media/pirate/STORAGE/System-Application/anaconda3/envs/Django_env/lib/python3.10/site-packages/kombu/transport/redis.py", line 737, in __init__
    self.client.ping()
  File "/run/media/pirate/STORAGE/System-Application/anaconda3/envs/Django_env/lib/python3.10/site-packages/redis/commands/core.py", line 1132, in ping
    return self.execute_command("PING", **kwargs)
  File "/run/media/pirate/STORAGE/System-Application/anaconda3/envs/Django_env/lib/python3.10/site-packages/redis/client.py", line 1235, in execute_command
    conn = self.connection or pool.get_connection(command_name, **options)
  File "/run/media/pirate/STORAGE/System-Application/anaconda3/envs/Django_env/lib/python3.10/site-packages/redis/connection.py", line 1387, in get_connection
    connection.connect()
  File "/run/media/pirate/STORAGE/System-Application/anaconda3/envs/Django_env/lib/python3.10/site-packages/redis/connection.py", line 617, in connect
    raise ConnectionError(self._error_message(e))
redis.exceptions.ConnectionError: Error 111 connecting to localhost:6379. Connection refused.

The above exception was the direct cause of the following exception:

Traceback (most recent call last):
  File "/run/media/pirate/STORAGE/System-Application/anaconda3/envs/Django_env/lib/python3.10/site-packages/celery/worker/worker.py", line 203, in start
    self.blueprint.start(self)
  File "/run/media/pirate/STORAGE/System-Application/anaconda3/envs/Django_env/lib/python3.10/site-packages/celery/bootsteps.py", line 116, in start
    step.start(parent)
  File "/run/media/pirate/STORAGE/System-Application/anaconda3/envs/Django_env/lib/python3.10/site-packages/celery/bootsteps.py", line 365, in start
    return self.obj.start()
  File "/run/media/pirate/STORAGE/System-Application/anaconda3/envs/Django_env/lib/python3.10/site-packages/celery/worker/consumer/consumer.py", line 332, in start
    blueprint.start(self)
  File "/run/media/pirate/STORAGE/System-Application/anaconda3/envs/Django_env/lib/python3.10/site-packages/celery/bootsteps.py", line 116, in start
    step.start(parent)
  File "/run/media/pirate/STORAGE/System-Application/anaconda3/envs/Django_env/lib/python3.10/site-packages/celery/worker/consumer/connection.py", line 21, in start
    c.connection = c.connect()
  File "/run/media/pirate/STORAGE/System-Application/anaconda3/envs/Django_env/lib/python3.10/site-packages/celery/worker/consumer/consumer.py", line 428, in connect
    conn = self.connection_for_read(heartbeat=self.amqheartbeat)
  File "/run/media/pirate/STORAGE/System-Application/anaconda3/envs/Django_env/lib/python3.10/site-packages/celery/worker/consumer/consumer.py", line 434, in connection_for_read
    return self.ensure_connected(
  File "/run/media/pirate/STORAGE/System-Application/anaconda3/envs/Django_env/lib/python3.10/site-packages/celery/worker/consumer/consumer.py", line 460, in ensure_connected
    conn = conn.ensure_connection(
  File "/run/media/pirate/STORAGE/System-Application/anaconda3/envs/Django_env/lib/python3.10/site-packages/kombu/connection.py", line 381, in ensure_connection
    self._ensure_connection(*args, **kwargs)
  File "/run/media/pirate/STORAGE/System-Application/anaconda3/envs/Django_env/lib/python3.10/site-packages/kombu/connection.py", line 432, in _ensure_connection
    with ctx():
  File "/run/media/pirate/STORAGE/System-Application/anaconda3/envs/Django_env/lib/python3.10/contextlib.py", line 153, in __exit__
    self.gen.throw(typ, value, traceback)
  File "/run/media/pirate/STORAGE/System-Application/anaconda3/envs/Django_env/lib/python3.10/site-packages/kombu/connection.py", line 450, in _reraise_as_library_errors
    raise ConnectionError(str(exc)) from exc
kombu.exceptions.OperationalError: Error 111 connecting to localhost:6379. Connection refused.
[2022-10-05 12:58:21,520: INFO/MainProcess] Connected to redis://localhost:6379//
[2022-10-05 12:58:21,525: INFO/MainProcess] mingle: searching for neighbors
[2022-10-05 12:58:22,535: INFO/MainProcess] mingle: all alone
[2022-10-05 12:58:22,682: WARNING/MainProcess] /run/media/pirate/STORAGE/System-Application/anaconda3/envs/Django_env/lib/python3.10/site-packages/celery/fixups/django.py:203: UserWarning: Using settings.DEBUG leads to a memory
            leak, never use this setting in production environments!
  warnings.warn('''Using settings.DEBUG leads to a memory

[2022-10-05 12:58:22,682: INFO/MainProcess] celery@Asteria ready.
[2022-10-05 12:58:22,685: INFO/MainProcess] Task celery.backend_cleanup[0fc8c6aa-2186-4c36-9635-c38bdcd6c1ab] received
[2022-10-05 12:58:22,689: INFO/ForkPoolWorker-7] Task celery.backend_cleanup[0fc8c6aa-2186-4c36-9635-c38bdcd6c1ab] succeeded in 0.0024214620007114718s: None
[2022-10-05 13:00:32,573: INFO/MainProcess] Task services.tasks.start_web_scraping_indeed[51d754f2-a9ce-47ff-a493-53404311128a] received
[2022-10-05 13:00:32,577: INFO/ForkPoolWorker-7] ====== WebDriver manager ======
[2022-10-05 13:00:32,981: INFO/ForkPoolWorker-7] Get LATEST chromedriver version for google-chrome 106.0.5249
[2022-10-05 13:00:39,170: INFO/ForkPoolWorker-7] There is no [linux64] chromedriver for browser 106.0.5249 in cache
[2022-10-05 13:00:39,170: INFO/ForkPoolWorker-7] About to download new driver from https://chromedriver.storage.googleapis.com/106.0.5249.61/chromedriver_linux64.zip
[2022-10-05 13:00:40,249: WARNING/ForkPoolWorker-7] [WDM] - Downloading:   0%|          | 0.00/6.35M [00:00<?, ?B/s]
[2022-10-05 13:00:40,418: WARNING/ForkPoolWorker-7] [WDM] - Downloading:   0%|          | 24.0k/6.35M [00:00<00:45, 146kB/s]
[2022-10-05 13:00:40,564: WARNING/ForkPoolWorker-7] [WDM] - Downloading:   1%|          | 40.0k/6.35M [00:00<00:52, 127kB/s]
[2022-10-05 13:00:40,670: WARNING/ForkPoolWorker-7] [WDM] - Downloading:   1%|1         | 72.0k/6.35M [00:00<00:34, 193kB/s]
[2022-10-05 13:00:40,782: WARNING/ForkPoolWorker-7] [WDM] - Downloading:   2%|1         | 128k/6.35M [00:00<00:21, 307kB/s] 
[2022-10-05 13:00:40,884: WARNING/ForkPoolWorker-7] [WDM] - Downloading:   3%|2         | 192k/6.35M [00:00<00:15, 413kB/s]
[2022-10-05 13:00:40,985: WARNING/ForkPoolWorker-7] [WDM] - Downloading:   5%|5         | 344k/6.35M [00:00<00:08, 762kB/s]
[2022-10-05 13:00:41,085: WARNING/ForkPoolWorker-7] [WDM] - Downloading:   7%|7         | 472k/6.35M [00:00<00:06, 927kB/s]
[2022-10-05 13:00:41,186: WARNING/ForkPoolWorker-7] [WDM] - Downloading:  12%|#1        | 752k/6.35M [00:00<00:03, 1.51MB/s]
[2022-10-05 13:00:41,289: WARNING/ForkPoolWorker-7] [WDM] - Downloading:  16%|#6        | 1.02M/6.35M [00:01<00:02, 1.95MB/s]
[2022-10-05 13:00:41,407: WARNING/ForkPoolWorker-7] [WDM] - Downloading:  20%|##        | 1.27M/6.35M [00:01<00:02, 2.04MB/s]
[2022-10-05 13:00:41,514: WARNING/ForkPoolWorker-7] [WDM] - Downloading:  25%|##5       | 1.62M/6.35M [00:01<00:02, 2.45MB/s]
[2022-10-05 13:00:41,617: WARNING/ForkPoolWorker-7] [WDM] - Downloading:  32%|###2      | 2.05M/6.35M [00:01<00:01, 3.04MB/s]
[2022-10-05 13:00:41,726: WARNING/ForkPoolWorker-7] [WDM] - Downloading:  39%|###8      | 2.45M/6.35M [00:01<00:01, 3.26MB/s]
[2022-10-05 13:00:41,829: WARNING/ForkPoolWorker-7] [WDM] - Downloading:  47%|####6     | 2.98M/6.35M [00:01<00:00, 3.89MB/s]
[2022-10-05 13:00:41,929: WARNING/ForkPoolWorker-7] [WDM] - Downloading:  54%|#####3    | 3.41M/6.35M [00:01<00:00, 4.09MB/s]
[2022-10-05 13:00:42,032: WARNING/ForkPoolWorker-7] [WDM] - Downloading:  60%|######    | 3.84M/6.35M [00:01<00:00, 4.15MB/s]
[2022-10-05 13:00:42,138: WARNING/ForkPoolWorker-7] [WDM] - Downloading:  67%|######7   | 4.27M/6.35M [00:01<00:00, 4.21MB/s]
[2022-10-05 13:00:42,242: WARNING/ForkPoolWorker-7] [WDM] - Downloading:  74%|#######3  | 4.68M/6.35M [00:01<00:00, 4.17MB/s]
[2022-10-05 13:00:42,342: WARNING/ForkPoolWorker-7] [WDM] - Downloading:  81%|########  | 5.13M/6.35M [00:02<00:00, 4.34MB/s]
[2022-10-05 13:00:42,456: WARNING/ForkPoolWorker-7] [WDM] - Downloading:  87%|########7 | 5.55M/6.35M [00:02<00:00, 4.19MB/s]
[2022-10-05 13:00:42,568: WARNING/ForkPoolWorker-7] [WDM] - Downloading:  94%|#########3| 5.96M/6.35M [00:02<00:00, 4.07MB/s]
[2022-10-05 13:00:42,662: WARNING/ForkPoolWorker-7] [WDM] - Downloading: 100%|##########| 6.35M/6.35M [00:02<00:00, 2.76MB/s]
[2022-10-05 13:00:42,932: INFO/ForkPoolWorker-7] Driver has been saved in cache [/home/pirate/.wdm/drivers/chromedriver/linux64/106.0.5249]
[2022-10-05 13:01:24,333: INFO/ForkPoolWorker-7] 54 Business Analyst - McKinsey Digital has been added to the database
[2022-10-05 13:01:24,598: INFO/ForkPoolWorker-7] 55 Executive Assistant has been added to the database
[2022-10-05 13:01:24,862: INFO/ForkPoolWorker-7] 56 Executive Assistant has been added to the database
[2022-10-05 13:01:25,126: INFO/ForkPoolWorker-7] 57 Process Excellence Manager has been added to the database
[2022-10-05 13:01:26,189: INFO/ForkPoolWorker-7] 58 Data Scientist - QuantumBlack has been added to the database
[2022-10-05 13:01:26,465: INFO/ForkPoolWorker-7] 59 Research Science Analyst - Panorama Financial Institutions C... has been added to the database
[2022-10-05 13:01:26,729: INFO/ForkPoolWorker-7] 60 Senior HR Administrator has been added to the database
[2022-10-05 13:01:26,994: INFO/ForkPoolWorker-7] 61 Associate Life Sciences has been added to the database
[2022-10-05 13:01:27,258: INFO/ForkPoolWorker-7] 62 Human Resources Generalist (Benefits) - INO has been added to the database
[2022-10-05 13:01:27,522: INFO/ForkPoolWorker-7] 63 Office Services Administrator has been added to the database
[2022-10-05 13:01:27,785: INFO/ForkPoolWorker-7] 64 Capabilities & Insights Analyst - Automotive & Assembly has been added to the database
[2022-10-05 13:01:28,050: INFO/ForkPoolWorker-7] 65 Capabilities and Insights Analyst_Payments Asia Hub_Gurugram has been added to the database
[2022-10-05 13:01:29,262: INFO/ForkPoolWorker-7] 66 Capabilities & Insights Team Leader - Client Capabilities Ne... has been added to the database
[2022-10-05 13:01:29,538: INFO/ForkPoolWorker-7] 67 Delivery Assurance Specialist has been added to the database
[2022-10-05 13:01:29,840: INFO/ForkPoolWorker-7] 68 Associate - Sustainability has been added to the database
[2022-10-05 13:01:29,841: INFO/ForkPoolWorker-7] None is not active
[2022-10-05 13:01:29,900: INFO/ForkPoolWorker-7] Task services.tasks.start_web_scraping_indeed[51d754f2-a9ce-47ff-a493-53404311128a] succeeded in 57.323482187999616s: None
[2022-10-06 15:38:16,796: ERROR/MainProcess] consumer: Cannot connect to redis://localhost:6379//: Error 111 connecting to localhost:6379. Connection refused..
Trying again in 2.00 seconds... (1/100)

[2022-10-06 15:38:18,800: ERROR/MainProcess] consumer: Cannot connect to redis://localhost:6379//: Error 111 connecting to localhost:6379. Connection refused..
Trying again in 4.00 seconds... (2/100)

[2022-10-06 15:38:22,807: ERROR/MainProcess] consumer: Cannot connect to redis://localhost:6379//: Error 111 connecting to localhost:6379. Connection refused..
Trying again in 6.00 seconds... (3/100)

[2022-10-06 15:38:28,816: ERROR/MainProcess] consumer: Cannot connect to redis://localhost:6379//: Error 111 connecting to localhost:6379. Connection refused..
Trying again in 8.00 seconds... (4/100)

[2022-10-06 15:38:36,827: INFO/MainProcess] Connected to redis://localhost:6379//
[2022-10-06 15:38:36,830: INFO/MainProcess] mingle: searching for neighbors
[2022-10-06 15:38:37,838: INFO/MainProcess] mingle: all alone
[2022-10-06 15:38:37,904: WARNING/MainProcess] /run/media/pirate/STORAGE/System-Application/anaconda3/envs/Django_env/lib/python3.10/site-packages/celery/fixups/django.py:203: UserWarning: Using settings.DEBUG leads to a memory
            leak, never use this setting in production environments!
  warnings.warn('''Using settings.DEBUG leads to a memory

[2022-10-06 15:38:37,904: INFO/MainProcess] celery@Asteria ready.
[2022-10-06 15:38:48,544: INFO/MainProcess] Task celery.backend_cleanup[e4d85fa2-c233-462c-becb-e44e2014a0cb] received
[2022-10-06 15:38:48,549: INFO/ForkPoolWorker-7] Task celery.backend_cleanup[e4d85fa2-c233-462c-becb-e44e2014a0cb] succeeded in 0.002400049997959286s: None
[2022-10-06 15:41:48,848: INFO/MainProcess] Task services.tasks.start_web_scraping_indeed[e5279311-1ef1-46d7-8050-397803f14275] received
[2022-10-06 15:41:48,850: INFO/ForkPoolWorker-7] ====== WebDriver manager ======
[2022-10-06 15:41:48,909: INFO/ForkPoolWorker-7] Get LATEST chromedriver version for google-chrome 106.0.5249
[2022-10-06 15:41:54,585: INFO/ForkPoolWorker-7] Driver [/home/pirate/.wdm/drivers/chromedriver/linux64/106.0.5249/chromedriver] found in cache
[2022-10-06 15:42:34,892: ERROR/ForkPoolWorker-7] Task services.tasks.start_web_scraping_indeed[e5279311-1ef1-46d7-8050-397803f14275] raised unexpected: AttributeError("'NoneType' object has no attribute 'find'")
Traceback (most recent call last):
  File "/run/media/pirate/STORAGE/System-Application/anaconda3/envs/Django_env/lib/python3.10/site-packages/celery/app/trace.py", line 451, in trace_task
    R = retval = fun(*args, **kwargs)
  File "/run/media/pirate/STORAGE/System-Application/anaconda3/envs/Django_env/lib/python3.10/site-packages/celery/app/trace.py", line 734, in __protected_call__
    return self.run(*args, **kwargs)
  File "/run/media/pirate/STORAGE/Pirate/Code-House/Web-Applications/jobWebsite/jobWebsite/services/tasks.py", line 48, in start_web_scraping_indeed
    company_logo = soup.find("div", class_="univsrch-ci-logo-small").find(
AttributeError: 'NoneType' object has no attribute 'find'
[2022-10-06 15:56:26,034: INFO/MainProcess] Task services.tasks.start_web_scraping_indeed[3c1937cf-c297-4a37-b071-1068ea7c4343] received
[2022-10-06 15:56:26,039: INFO/ForkPoolWorker-7] ====== WebDriver manager ======
[2022-10-06 15:56:26,097: INFO/ForkPoolWorker-7] Get LATEST chromedriver version for google-chrome 106.0.5249
[2022-10-06 15:56:32,029: INFO/ForkPoolWorker-7] Driver [/home/pirate/.wdm/drivers/chromedriver/linux64/106.0.5249/chromedriver] found in cache
[2022-10-06 15:57:06,994: ERROR/ForkPoolWorker-7] Task services.tasks.start_web_scraping_indeed[3c1937cf-c297-4a37-b071-1068ea7c4343] raised unexpected: AttributeError("'NoneType' object has no attribute 'find'")
Traceback (most recent call last):
  File "/run/media/pirate/STORAGE/System-Application/anaconda3/envs/Django_env/lib/python3.10/site-packages/celery/app/trace.py", line 451, in trace_task
    R = retval = fun(*args, **kwargs)
  File "/run/media/pirate/STORAGE/System-Application/anaconda3/envs/Django_env/lib/python3.10/site-packages/celery/app/trace.py", line 734, in __protected_call__
    return self.run(*args, **kwargs)
  File "/run/media/pirate/STORAGE/Pirate/Code-House/Web-Applications/jobWebsite/jobWebsite/services/tasks.py", line 48, in start_web_scraping_indeed
    for card in jobs_card:
AttributeError: 'NoneType' object has no attribute 'find'
[2022-10-06 16:24:53,250: INFO/MainProcess] Connected to redis://localhost:6379//
[2022-10-06 16:24:53,255: INFO/MainProcess] mingle: searching for neighbors
[2022-10-06 16:24:54,267: INFO/MainProcess] mingle: all alone
[2022-10-06 16:24:54,300: WARNING/MainProcess] /run/media/pirate/STORAGE/System-Application/anaconda3/envs/Django_env/lib/python3.10/site-packages/celery/fixups/django.py:203: UserWarning: Using settings.DEBUG leads to a memory
            leak, never use this setting in production environments!
  warnings.warn('''Using settings.DEBUG leads to a memory

[2022-10-06 16:24:54,300: INFO/MainProcess] celery@Asteria ready.
[2022-10-06 16:27:01,266: INFO/MainProcess] Task services.tasks.start_web_scraping_indeed[ce17ef89-f1d3-4e0c-8ce4-6f00548b2d48] received
[2022-10-06 16:27:01,268: INFO/ForkPoolWorker-7] ====== WebDriver manager ======
[2022-10-06 16:27:01,315: INFO/ForkPoolWorker-7] Get LATEST chromedriver version for google-chrome 106.0.5249
[2022-10-06 16:27:07,280: INFO/ForkPoolWorker-7] Driver [/home/pirate/.wdm/drivers/chromedriver/linux64/106.0.5249/chromedriver] found in cache
[2022-10-06 16:28:08,591: ERROR/ForkPoolWorker-7] Task services.tasks.start_web_scraping_indeed[ce17ef89-f1d3-4e0c-8ce4-6f00548b2d48] raised unexpected: NoSuchElementException('no such element: Unable to locate element: {"method":"xpath","selector":"//*[@id="jobDescriptionText"]/div/div[2]/div/div"}\n  (Session info: chrome=106.0.5249.61)', None, ['#0 0x562352bbb2c3 <unknown>', '#1 0x5623529c483a <unknown>', '#2 0x5623529fd985 <unknown>', '#3 0x5623529fdb61 <unknown>', '#4 0x562352a35d14 <unknown>', '#5 0x562352a1bf6d <unknown>', '#6 0x562352a33a50 <unknown>', '#7 0x562352a1bd63 <unknown>', '#8 0x5623529f07e3 <unknown>', '#9 0x5623529f1a21 <unknown>', '#10 0x562352c0918e <unknown>', '#11 0x562352c0c622 <unknown>', '#12 0x562352befaae <unknown>', '#13 0x562352c0d2a3 <unknown>', '#14 0x562352be3ecf <unknown>', '#15 0x562352c2d588 <unknown>', '#16 0x562352c2d706 <unknown>', '#17 0x562352c478b2 <unknown>', '#18 0x7f04c45c074d <unknown>', ''])
Traceback (most recent call last):
  File "/run/media/pirate/STORAGE/System-Application/anaconda3/envs/Django_env/lib/python3.10/site-packages/celery/app/trace.py", line 451, in trace_task
    R = retval = fun(*args, **kwargs)
  File "/run/media/pirate/STORAGE/System-Application/anaconda3/envs/Django_env/lib/python3.10/site-packages/celery/app/trace.py", line 734, in __protected_call__
    return self.run(*args, **kwargs)
  File "/run/media/pirate/STORAGE/Pirate/Code-House/Web-Applications/jobWebsite/jobWebsite/services/tasks.py", line 68, in start_web_scraping_indeed
    qualifications = driver.find_element(By.XPATH, '//*[@id="jobDescriptionText"]/div/div[3]/div/div')
  File "/run/media/pirate/STORAGE/System-Application/anaconda3/envs/Django_env/lib/python3.10/site-packages/selenium/webdriver/remote/webdriver.py", line 855, in find_element
    return self.execute(Command.FIND_ELEMENT, {
  File "/run/media/pirate/STORAGE/System-Application/anaconda3/envs/Django_env/lib/python3.10/site-packages/selenium/webdriver/remote/webdriver.py", line 428, in execute
    self.error_handler.check_response(response)
  File "/run/media/pirate/STORAGE/System-Application/anaconda3/envs/Django_env/lib/python3.10/site-packages/selenium/webdriver/remote/errorhandler.py", line 243, in check_response
    raise exception_class(message, screen, stacktrace)
selenium.common.exceptions.NoSuchElementException: Message: no such element: Unable to locate element: {"method":"xpath","selector":"//*[@id="jobDescriptionText"]/div/div[2]/div/div"}
  (Session info: chrome=106.0.5249.61)
Stacktrace:
#0 0x562352bbb2c3 <unknown>
#1 0x5623529c483a <unknown>
#2 0x5623529fd985 <unknown>
#3 0x5623529fdb61 <unknown>
#4 0x562352a35d14 <unknown>
#5 0x562352a1bf6d <unknown>
#6 0x562352a33a50 <unknown>
#7 0x562352a1bd63 <unknown>
#8 0x5623529f07e3 <unknown>
#9 0x5623529f1a21 <unknown>
#10 0x562352c0918e <unknown>
#11 0x562352c0c622 <unknown>
#12 0x562352befaae <unknown>
#13 0x562352c0d2a3 <unknown>
#14 0x562352be3ecf <unknown>
#15 0x562352c2d588 <unknown>
#16 0x562352c2d706 <unknown>
#17 0x562352c478b2 <unknown>
#18 0x7f04c45c074d <unknown>

[2022-10-06 16:29:37,552: INFO/MainProcess] Task services.tasks.start_web_scraping_indeed[6e1c0d87-e705-4925-8f17-a9fe84e63273] received
[2022-10-06 16:29:37,555: INFO/ForkPoolWorker-7] ====== WebDriver manager ======
[2022-10-06 16:29:37,650: INFO/ForkPoolWorker-7] Get LATEST chromedriver version for google-chrome 106.0.5249
[2022-10-06 16:29:38,376: INFO/ForkPoolWorker-7] Driver [/home/pirate/.wdm/drivers/chromedriver/linux64/106.0.5249/chromedriver] found in cache
[2022-10-06 16:30:25,430: ERROR/ForkPoolWorker-7] Task services.tasks.start_web_scraping_indeed[6e1c0d87-e705-4925-8f17-a9fe84e63273] raised unexpected: NoSuchElementException('no such element: Unable to locate element: {"method":"xpath","selector":"//*[@id="jobDescriptionText"]/div/div[2]/div/div"}\n  (Session info: chrome=106.0.5249.61)', None, ['#0 0x55fbe28ff2c3 <unknown>', '#1 0x55fbe270883a <unknown>', '#2 0x55fbe2741985 <unknown>', '#3 0x55fbe2741b61 <unknown>', '#4 0x55fbe2779d14 <unknown>', '#5 0x55fbe275ff6d <unknown>', '#6 0x55fbe2777a50 <unknown>', '#7 0x55fbe275fd63 <unknown>', '#8 0x55fbe27347e3 <unknown>', '#9 0x55fbe2735a21 <unknown>', '#10 0x55fbe294d18e <unknown>', '#11 0x55fbe2950622 <unknown>', '#12 0x55fbe2933aae <unknown>', '#13 0x55fbe29512a3 <unknown>', '#14 0x55fbe2927ecf <unknown>', '#15 0x55fbe2971588 <unknown>', '#16 0x55fbe2971706 <unknown>', '#17 0x55fbe298b8b2 <unknown>', '#18 0x7fc746e7074d <unknown>', ''])
Traceback (most recent call last):
  File "/run/media/pirate/STORAGE/System-Application/anaconda3/envs/Django_env/lib/python3.10/site-packages/celery/app/trace.py", line 451, in trace_task
    R = retval = fun(*args, **kwargs)
  File "/run/media/pirate/STORAGE/System-Application/anaconda3/envs/Django_env/lib/python3.10/site-packages/celery/app/trace.py", line 734, in __protected_call__
    return self.run(*args, **kwargs)
  File "/run/media/pirate/STORAGE/Pirate/Code-House/Web-Applications/jobWebsite/jobWebsite/services/tasks.py", line 68, in start_web_scraping_indeed
    qualifications = driver.find_element(By.XPATH, '//*[@id="jobDescriptionText"]/div/div[3]/div/div')
  File "/run/media/pirate/STORAGE/System-Application/anaconda3/envs/Django_env/lib/python3.10/site-packages/selenium/webdriver/remote/webdriver.py", line 855, in find_element
    return self.execute(Command.FIND_ELEMENT, {
  File "/run/media/pirate/STORAGE/System-Application/anaconda3/envs/Django_env/lib/python3.10/site-packages/selenium/webdriver/remote/webdriver.py", line 428, in execute
    self.error_handler.check_response(response)
  File "/run/media/pirate/STORAGE/System-Application/anaconda3/envs/Django_env/lib/python3.10/site-packages/selenium/webdriver/remote/errorhandler.py", line 243, in check_response
    raise exception_class(message, screen, stacktrace)
selenium.common.exceptions.NoSuchElementException: Message: no such element: Unable to locate element: {"method":"xpath","selector":"//*[@id="jobDescriptionText"]/div/div[2]/div/div"}
  (Session info: chrome=106.0.5249.61)
Stacktrace:
#0 0x55fbe28ff2c3 <unknown>
#1 0x55fbe270883a <unknown>
#2 0x55fbe2741985 <unknown>
#3 0x55fbe2741b61 <unknown>
#4 0x55fbe2779d14 <unknown>
#5 0x55fbe275ff6d <unknown>
#6 0x55fbe2777a50 <unknown>
#7 0x55fbe275fd63 <unknown>
#8 0x55fbe27347e3 <unknown>
#9 0x55fbe2735a21 <unknown>
#10 0x55fbe294d18e <unknown>
#11 0x55fbe2950622 <unknown>
#12 0x55fbe2933aae <unknown>
#13 0x55fbe29512a3 <unknown>
#14 0x55fbe2927ecf <unknown>
#15 0x55fbe2971588 <unknown>
#16 0x55fbe2971706 <unknown>
#17 0x55fbe298b8b2 <unknown>
#18 0x7fc746e7074d <unknown>

[2022-10-06 16:33:39,194: INFO/MainProcess] Task services.tasks.start_web_scraping_indeed[e065c7cd-237f-4648-b5e1-327c91400568] received
[2022-10-06 16:33:39,198: INFO/ForkPoolWorker-7] ====== WebDriver manager ======
[2022-10-06 16:33:39,293: INFO/ForkPoolWorker-7] Get LATEST chromedriver version for google-chrome 106.0.5249
[2022-10-06 16:33:46,365: INFO/ForkPoolWorker-7] Driver [/home/pirate/.wdm/drivers/chromedriver/linux64/106.0.5249/chromedriver] found in cache
[2022-10-06 16:34:44,115: ERROR/ForkPoolWorker-7] Task services.tasks.start_web_scraping_indeed[e065c7cd-237f-4648-b5e1-327c91400568] raised unexpected: NoSuchElementException('no such element: Unable to locate element: {"method":"xpath","selector":"//*[@id="jobDescriptionText"]/div/div[2]/div/div"}\n  (Session info: chrome=106.0.5249.61)', None, ['#0 0x558d31a182c3 <unknown>', '#1 0x558d3182183a <unknown>', '#2 0x558d3185a985 <unknown>', '#3 0x558d3185ab61 <unknown>', '#4 0x558d31892d14 <unknown>', '#5 0x558d31878f6d <unknown>', '#6 0x558d31890a50 <unknown>', '#7 0x558d31878d63 <unknown>', '#8 0x558d3184d7e3 <unknown>', '#9 0x558d3184ea21 <unknown>', '#10 0x558d31a6618e <unknown>', '#11 0x558d31a69622 <unknown>', '#12 0x558d31a4caae <unknown>', '#13 0x558d31a6a2a3 <unknown>', '#14 0x558d31a40ecf <unknown>', '#15 0x558d31a8a588 <unknown>', '#16 0x558d31a8a706 <unknown>', '#17 0x558d31aa48b2 <unknown>', '#18 0x7fcdf197374d <unknown>', ''])
Traceback (most recent call last):
  File "/run/media/pirate/STORAGE/System-Application/anaconda3/envs/Django_env/lib/python3.10/site-packages/celery/app/trace.py", line 451, in trace_task
    R = retval = fun(*args, **kwargs)
  File "/run/media/pirate/STORAGE/System-Application/anaconda3/envs/Django_env/lib/python3.10/site-packages/celery/app/trace.py", line 734, in __protected_call__
    return self.run(*args, **kwargs)
  File "/run/media/pirate/STORAGE/Pirate/Code-House/Web-Applications/jobWebsite/jobWebsite/services/tasks.py", line 68, in start_web_scraping_indeed
    time.sleep(10)
  File "/run/media/pirate/STORAGE/System-Application/anaconda3/envs/Django_env/lib/python3.10/site-packages/selenium/webdriver/remote/webdriver.py", line 855, in find_element
    return self.execute(Command.FIND_ELEMENT, {
  File "/run/media/pirate/STORAGE/System-Application/anaconda3/envs/Django_env/lib/python3.10/site-packages/selenium/webdriver/remote/webdriver.py", line 428, in execute
    self.error_handler.check_response(response)
  File "/run/media/pirate/STORAGE/System-Application/anaconda3/envs/Django_env/lib/python3.10/site-packages/selenium/webdriver/remote/errorhandler.py", line 243, in check_response
    raise exception_class(message, screen, stacktrace)
selenium.common.exceptions.NoSuchElementException: Message: no such element: Unable to locate element: {"method":"xpath","selector":"//*[@id="jobDescriptionText"]/div/div[2]/div/div"}
  (Session info: chrome=106.0.5249.61)
Stacktrace:
#0 0x558d31a182c3 <unknown>
#1 0x558d3182183a <unknown>
#2 0x558d3185a985 <unknown>
#3 0x558d3185ab61 <unknown>
#4 0x558d31892d14 <unknown>
#5 0x558d31878f6d <unknown>
#6 0x558d31890a50 <unknown>
#7 0x558d31878d63 <unknown>
#8 0x558d3184d7e3 <unknown>
#9 0x558d3184ea21 <unknown>
#10 0x558d31a6618e <unknown>
#11 0x558d31a69622 <unknown>
#12 0x558d31a4caae <unknown>
#13 0x558d31a6a2a3 <unknown>
#14 0x558d31a40ecf <unknown>
#15 0x558d31a8a588 <unknown>
#16 0x558d31a8a706 <unknown>
#17 0x558d31aa48b2 <unknown>
#18 0x7fcdf197374d <unknown>

[2022-10-06 16:36:45,498: INFO/MainProcess] Task services.tasks.start_web_scraping_indeed[9d83cf14-005b-49f4-8fc6-d73cb02c6edb] received
[2022-10-06 16:36:45,502: INFO/ForkPoolWorker-7] ====== WebDriver manager ======
[2022-10-06 16:36:45,624: INFO/ForkPoolWorker-7] Get LATEST chromedriver version for google-chrome 106.0.5249
[2022-10-06 16:36:46,264: INFO/ForkPoolWorker-7] Driver [/home/pirate/.wdm/drivers/chromedriver/linux64/106.0.5249/chromedriver] found in cache
[2022-10-06 16:37:47,604: ERROR/ForkPoolWorker-7] Task services.tasks.start_web_scraping_indeed[9d83cf14-005b-49f4-8fc6-d73cb02c6edb] raised unexpected: NoSuchElementException('no such element: Unable to locate element: {"method":"xpath","selector":"//*[@id="jobDescriptionText"]/div/div[2]/div/div"}\n  (Session info: chrome=106.0.5249.61)', None, ['#0 0x562570a142c3 <unknown>', '#1 0x56257081d83a <unknown>', '#2 0x562570856985 <unknown>', '#3 0x562570856b61 <unknown>', '#4 0x56257088ed14 <unknown>', '#5 0x562570874f6d <unknown>', '#6 0x56257088ca50 <unknown>', '#7 0x562570874d63 <unknown>', '#8 0x5625708497e3 <unknown>', '#9 0x56257084aa21 <unknown>', '#10 0x562570a6218e <unknown>', '#11 0x562570a65622 <unknown>', '#12 0x562570a48aae <unknown>', '#13 0x562570a662a3 <unknown>', '#14 0x562570a3cecf <unknown>', '#15 0x562570a86588 <unknown>', '#16 0x562570a86706 <unknown>', '#17 0x562570aa08b2 <unknown>', '#18 0x7fd86873d74d <unknown>', ''])
Traceback (most recent call last):
  File "/run/media/pirate/STORAGE/System-Application/anaconda3/envs/Django_env/lib/python3.10/site-packages/celery/app/trace.py", line 451, in trace_task
    R = retval = fun(*args, **kwargs)
  File "/run/media/pirate/STORAGE/System-Application/anaconda3/envs/Django_env/lib/python3.10/site-packages/celery/app/trace.py", line 734, in __protected_call__
    return self.run(*args, **kwargs)
  File "/run/media/pirate/STORAGE/Pirate/Code-House/Web-Applications/jobWebsite/jobWebsite/services/tasks.py", line 68, in start_web_scraping_indeed
    time.sleep(10)
  File "/run/media/pirate/STORAGE/System-Application/anaconda3/envs/Django_env/lib/python3.10/site-packages/selenium/webdriver/remote/webdriver.py", line 855, in find_element
    return self.execute(Command.FIND_ELEMENT, {
  File "/run/media/pirate/STORAGE/System-Application/anaconda3/envs/Django_env/lib/python3.10/site-packages/selenium/webdriver/remote/webdriver.py", line 428, in execute
    self.error_handler.check_response(response)
  File "/run/media/pirate/STORAGE/System-Application/anaconda3/envs/Django_env/lib/python3.10/site-packages/selenium/webdriver/remote/errorhandler.py", line 243, in check_response
    raise exception_class(message, screen, stacktrace)
selenium.common.exceptions.NoSuchElementException: Message: no such element: Unable to locate element: {"method":"xpath","selector":"//*[@id="jobDescriptionText"]/div/div[2]/div/div"}
  (Session info: chrome=106.0.5249.61)
Stacktrace:
#0 0x562570a142c3 <unknown>
#1 0x56257081d83a <unknown>
#2 0x562570856985 <unknown>
#3 0x562570856b61 <unknown>
#4 0x56257088ed14 <unknown>
#5 0x562570874f6d <unknown>
#6 0x56257088ca50 <unknown>
#7 0x562570874d63 <unknown>
#8 0x5625708497e3 <unknown>
#9 0x56257084aa21 <unknown>
#10 0x562570a6218e <unknown>
#11 0x562570a65622 <unknown>
#12 0x562570a48aae <unknown>
#13 0x562570a662a3 <unknown>
#14 0x562570a3cecf <unknown>
#15 0x562570a86588 <unknown>
#16 0x562570a86706 <unknown>
#17 0x562570aa08b2 <unknown>
#18 0x7fd86873d74d <unknown>

[2022-10-06 16:40:07,565: INFO/MainProcess] Task services.tasks.start_web_scraping_indeed[ad7a2a67-2f41-436a-b5bd-877792788ae6] received
[2022-10-06 16:40:07,569: INFO/ForkPoolWorker-7] ====== WebDriver manager ======
[2022-10-06 16:40:07,677: INFO/ForkPoolWorker-7] Get LATEST chromedriver version for google-chrome 106.0.5249
[2022-10-06 16:40:13,277: INFO/ForkPoolWorker-7] Driver [/home/pirate/.wdm/drivers/chromedriver/linux64/106.0.5249/chromedriver] found in cache
[2022-10-06 16:41:05,463: ERROR/ForkPoolWorker-7] Task services.tasks.start_web_scraping_indeed[ad7a2a67-2f41-436a-b5bd-877792788ae6] raised unexpected: NoSuchElementException('no such element: Unable to locate element: {"method":"xpath","selector":"//*[@id="jobDescriptionText"]/div/div[2]/div/div"}\n  (Session info: chrome=106.0.5249.61)', None, ['#0 0x559189e042c3 <unknown>', '#1 0x559189c0d83a <unknown>', '#2 0x559189c46985 <unknown>', '#3 0x559189c46b61 <unknown>', '#4 0x559189c7ed14 <unknown>', '#5 0x559189c64f6d <unknown>', '#6 0x559189c7ca50 <unknown>', '#7 0x559189c64d63 <unknown>', '#8 0x559189c397e3 <unknown>', '#9 0x559189c3aa21 <unknown>', '#10 0x559189e5218e <unknown>', '#11 0x559189e55622 <unknown>', '#12 0x559189e38aae <unknown>', '#13 0x559189e562a3 <unknown>', '#14 0x559189e2cecf <unknown>', '#15 0x559189e76588 <unknown>', '#16 0x559189e76706 <unknown>', '#17 0x559189e908b2 <unknown>', '#18 0x7f4aa38de74d <unknown>', ''])
Traceback (most recent call last):
  File "/run/media/pirate/STORAGE/System-Application/anaconda3/envs/Django_env/lib/python3.10/site-packages/celery/app/trace.py", line 451, in trace_task
    R = retval = fun(*args, **kwargs)
  File "/run/media/pirate/STORAGE/System-Application/anaconda3/envs/Django_env/lib/python3.10/site-packages/celery/app/trace.py", line 734, in __protected_call__
    return self.run(*args, **kwargs)
  File "/run/media/pirate/STORAGE/Pirate/Code-House/Web-Applications/jobWebsite/jobWebsite/services/tasks.py", line 68, in start_web_scraping_indeed
    driver.get(url_link_new)
  File "/run/media/pirate/STORAGE/System-Application/anaconda3/envs/Django_env/lib/python3.10/site-packages/selenium/webdriver/remote/webdriver.py", line 855, in find_element
    return self.execute(Command.FIND_ELEMENT, {
  File "/run/media/pirate/STORAGE/System-Application/anaconda3/envs/Django_env/lib/python3.10/site-packages/selenium/webdriver/remote/webdriver.py", line 428, in execute
    self.error_handler.check_response(response)
  File "/run/media/pirate/STORAGE/System-Application/anaconda3/envs/Django_env/lib/python3.10/site-packages/selenium/webdriver/remote/errorhandler.py", line 243, in check_response
    raise exception_class(message, screen, stacktrace)
selenium.common.exceptions.NoSuchElementException: Message: no such element: Unable to locate element: {"method":"xpath","selector":"//*[@id="jobDescriptionText"]/div/div[2]/div/div"}
  (Session info: chrome=106.0.5249.61)
Stacktrace:
#0 0x559189e042c3 <unknown>
#1 0x559189c0d83a <unknown>
#2 0x559189c46985 <unknown>
#3 0x559189c46b61 <unknown>
#4 0x559189c7ed14 <unknown>
#5 0x559189c64f6d <unknown>
#6 0x559189c7ca50 <unknown>
#7 0x559189c64d63 <unknown>
#8 0x559189c397e3 <unknown>
#9 0x559189c3aa21 <unknown>
#10 0x559189e5218e <unknown>
#11 0x559189e55622 <unknown>
#12 0x559189e38aae <unknown>
#13 0x559189e562a3 <unknown>
#14 0x559189e2cecf <unknown>
#15 0x559189e76588 <unknown>
#16 0x559189e76706 <unknown>
#17 0x559189e908b2 <unknown>
#18 0x7f4aa38de74d <unknown>

[2022-10-06 16:44:48,997: INFO/MainProcess] Task services.tasks.start_web_scraping_indeed[dc49b689-deff-4d1b-b5d6-ff0a34bcc210] received
[2022-10-06 16:44:49,001: INFO/ForkPoolWorker-7] ====== WebDriver manager ======
[2022-10-06 16:44:49,073: INFO/ForkPoolWorker-7] Get LATEST chromedriver version for google-chrome 106.0.5249
[2022-10-06 16:44:49,854: INFO/ForkPoolWorker-7] Driver [/home/pirate/.wdm/drivers/chromedriver/linux64/106.0.5249/chromedriver] found in cache
[2022-10-06 16:45:40,307: ERROR/ForkPoolWorker-7] Task services.tasks.start_web_scraping_indeed[dc49b689-deff-4d1b-b5d6-ff0a34bcc210] raised unexpected: NoSuchElementException('no such element: Unable to locate element: {"method":"xpath","selector":"//*[@id="jobDescriptionText"]/div/div[2]/div/div"}\n  (Session info: chrome=106.0.5249.61)', None, ['#0 0x55f99b2942c3 <unknown>', '#1 0x55f99b09d83a <unknown>', '#2 0x55f99b0d6985 <unknown>', '#3 0x55f99b0d6b61 <unknown>', '#4 0x55f99b10ed14 <unknown>', '#5 0x55f99b0f4f6d <unknown>', '#6 0x55f99b10ca50 <unknown>', '#7 0x55f99b0f4d63 <unknown>', '#8 0x55f99b0c97e3 <unknown>', '#9 0x55f99b0caa21 <unknown>', '#10 0x55f99b2e218e <unknown>', '#11 0x55f99b2e5622 <unknown>', '#12 0x55f99b2c8aae <unknown>', '#13 0x55f99b2e62a3 <unknown>', '#14 0x55f99b2bcecf <unknown>', '#15 0x55f99b306588 <unknown>', '#16 0x55f99b306706 <unknown>', '#17 0x55f99b3208b2 <unknown>', '#18 0x7f732b43074d <unknown>', ''])
Traceback (most recent call last):
  File "/run/media/pirate/STORAGE/System-Application/anaconda3/envs/Django_env/lib/python3.10/site-packages/celery/app/trace.py", line 451, in trace_task
    R = retval = fun(*args, **kwargs)
  File "/run/media/pirate/STORAGE/System-Application/anaconda3/envs/Django_env/lib/python3.10/site-packages/celery/app/trace.py", line 734, in __protected_call__
    return self.run(*args, **kwargs)
  File "/run/media/pirate/STORAGE/Pirate/Code-House/Web-Applications/jobWebsite/jobWebsite/services/tasks.py", line 68, in start_web_scraping_indeed
    time.sleep(10)
  File "/run/media/pirate/STORAGE/System-Application/anaconda3/envs/Django_env/lib/python3.10/site-packages/selenium/webdriver/remote/webdriver.py", line 855, in find_element
    return self.execute(Command.FIND_ELEMENT, {
  File "/run/media/pirate/STORAGE/System-Application/anaconda3/envs/Django_env/lib/python3.10/site-packages/selenium/webdriver/remote/webdriver.py", line 428, in execute
    self.error_handler.check_response(response)
  File "/run/media/pirate/STORAGE/System-Application/anaconda3/envs/Django_env/lib/python3.10/site-packages/selenium/webdriver/remote/errorhandler.py", line 243, in check_response
    raise exception_class(message, screen, stacktrace)
selenium.common.exceptions.NoSuchElementException: Message: no such element: Unable to locate element: {"method":"xpath","selector":"//*[@id="jobDescriptionText"]/div/div[2]/div/div"}
  (Session info: chrome=106.0.5249.61)
Stacktrace:
#0 0x55f99b2942c3 <unknown>
#1 0x55f99b09d83a <unknown>
#2 0x55f99b0d6985 <unknown>
#3 0x55f99b0d6b61 <unknown>
#4 0x55f99b10ed14 <unknown>
#5 0x55f99b0f4f6d <unknown>
#6 0x55f99b10ca50 <unknown>
#7 0x55f99b0f4d63 <unknown>
#8 0x55f99b0c97e3 <unknown>
#9 0x55f99b0caa21 <unknown>
#10 0x55f99b2e218e <unknown>
#11 0x55f99b2e5622 <unknown>
#12 0x55f99b2c8aae <unknown>
#13 0x55f99b2e62a3 <unknown>
#14 0x55f99b2bcecf <unknown>
#15 0x55f99b306588 <unknown>
#16 0x55f99b306706 <unknown>
#17 0x55f99b3208b2 <unknown>
#18 0x7f732b43074d <unknown>

[2022-10-06 16:52:57,329: INFO/MainProcess] Connected to redis://localhost:6379//
[2022-10-06 16:52:57,332: INFO/MainProcess] mingle: searching for neighbors
[2022-10-06 16:52:58,343: INFO/MainProcess] mingle: all alone
[2022-10-06 16:52:58,379: WARNING/MainProcess] /run/media/pirate/STORAGE/System-Application/anaconda3/envs/Django_env/lib/python3.10/site-packages/celery/fixups/django.py:203: UserWarning: Using settings.DEBUG leads to a memory
            leak, never use this setting in production environments!
  warnings.warn('''Using settings.DEBUG leads to a memory

[2022-10-06 16:52:58,379: INFO/MainProcess] celery@Asteria ready.
[2022-10-06 16:54:25,434: INFO/MainProcess] Task services.tasks.start_web_scraping_indeed[f50fa973-c3cd-449d-bd81-7250c78f501a] received
[2022-10-06 16:54:25,436: INFO/ForkPoolWorker-7] ====== WebDriver manager ======
[2022-10-06 16:54:25,489: INFO/ForkPoolWorker-7] Get LATEST chromedriver version for google-chrome 106.0.5249
[2022-10-06 16:54:31,234: INFO/ForkPoolWorker-7] Driver [/home/pirate/.wdm/drivers/chromedriver/linux64/106.0.5249/chromedriver] found in cache
[2022-10-06 16:55:12,122: WARNING/ForkPoolWorker-7] https://in.indeed.com/rc/clk?jk=e78be0bd2d4d8a84&fccid=6576e7250aa78c3c&vjs=3
[2022-10-06 16:55:47,139: INFO/ForkPoolWorker-7] 69 Business Analyst - McKinsey Digital has been added to the database
[2022-10-06 16:55:47,140: WARNING/ForkPoolWorker-7] https://in.indeed.com/rc/clk?jk=e371e9c75190de1d&fccid=6576e7250aa78c3c&vjs=3
[2022-10-06 16:56:11,685: INFO/ForkPoolWorker-7] 70 Executive Assistant has been added to the database
[2022-10-06 16:56:11,687: WARNING/ForkPoolWorker-7] https://in.indeed.com/rc/clk?jk=606910015e7c5e93&fccid=6576e7250aa78c3c&vjs=3
[2022-10-06 16:56:35,819: INFO/ForkPoolWorker-7] 71 Junior Capabilities & Insights Analyst - Automotive & Assemb... has been added to the database
[2022-10-06 16:56:35,820: WARNING/ForkPoolWorker-7] https://in.indeed.com/rc/clk?jk=299d47822ca40531&fccid=6576e7250aa78c3c&vjs=3
[2022-10-06 16:56:59,432: ERROR/ForkPoolWorker-7] Task services.tasks.start_web_scraping_indeed[f50fa973-c3cd-449d-bd81-7250c78f501a] raised unexpected: NoSuchWindowException('no such window: target window already closed\nfrom unknown error: web view not found\n  (Session info: chrome=106.0.5249.61)', None, ['#0 0x55a6e7eba2c3 <unknown>', '#1 0x55a6e7cc383a <unknown>', '#2 0x55a6e7ca28e3 <unknown>', '#3 0x55a6e7d1eebd <unknown>', '#4 0x55a6e7d32029 <unknown>', '#5 0x55a6e7d1ad63 <unknown>', '#6 0x55a6e7cef7e3 <unknown>', '#7 0x55a6e7cf0a21 <unknown>', '#8 0x55a6e7f0818e <unknown>', '#9 0x55a6e7f0b622 <unknown>', '#10 0x55a6e7eeeaae <unknown>', '#11 0x55a6e7f0c2a3 <unknown>', '#12 0x55a6e7ee2ecf <unknown>', '#13 0x55a6e7f2c588 <unknown>', '#14 0x55a6e7f2c706 <unknown>', '#15 0x55a6e7f468b2 <unknown>', '#16 0x7f4ef07ce74d <unknown>', ''])
Traceback (most recent call last):
  File "/run/media/pirate/STORAGE/System-Application/anaconda3/envs/Django_env/lib/python3.10/site-packages/celery/app/trace.py", line 451, in trace_task
    R = retval = fun(*args, **kwargs)
  File "/run/media/pirate/STORAGE/System-Application/anaconda3/envs/Django_env/lib/python3.10/site-packages/celery/app/trace.py", line 734, in __protected_call__
    return self.run(*args, **kwargs)
  File "/run/media/pirate/STORAGE/Pirate/Code-House/Web-Applications/jobWebsite/jobWebsite/services/tasks.py", line 75, in start_web_scraping_indeed
    company_logo = driver.find_element(By.XPATH, '//*[@id="cmp-container"]/div/div[1]/header/div[2]/div[3]/div/div/div/div[1]/div[1]/div[1]/div/div/img').get_attribute('src')
  File "/run/media/pirate/STORAGE/System-Application/anaconda3/envs/Django_env/lib/python3.10/site-packages/selenium/webdriver/remote/webdriver.py", line 855, in find_element
    return self.execute(Command.FIND_ELEMENT, {
  File "/run/media/pirate/STORAGE/System-Application/anaconda3/envs/Django_env/lib/python3.10/site-packages/selenium/webdriver/remote/webdriver.py", line 428, in execute
    self.error_handler.check_response(response)
  File "/run/media/pirate/STORAGE/System-Application/anaconda3/envs/Django_env/lib/python3.10/site-packages/selenium/webdriver/remote/errorhandler.py", line 243, in check_response
    raise exception_class(message, screen, stacktrace)
selenium.common.exceptions.NoSuchWindowException: Message: no such window: target window already closed
from unknown error: web view not found
  (Session info: chrome=106.0.5249.61)
Stacktrace:
#0 0x55a6e7eba2c3 <unknown>
#1 0x55a6e7cc383a <unknown>
#2 0x55a6e7ca28e3 <unknown>
#3 0x55a6e7d1eebd <unknown>
#4 0x55a6e7d32029 <unknown>
#5 0x55a6e7d1ad63 <unknown>
#6 0x55a6e7cef7e3 <unknown>
#7 0x55a6e7cf0a21 <unknown>
#8 0x55a6e7f0818e <unknown>
#9 0x55a6e7f0b622 <unknown>
#10 0x55a6e7eeeaae <unknown>
#11 0x55a6e7f0c2a3 <unknown>
#12 0x55a6e7ee2ecf <unknown>
#13 0x55a6e7f2c588 <unknown>
#14 0x55a6e7f2c706 <unknown>
#15 0x55a6e7f468b2 <unknown>
#16 0x7f4ef07ce74d <unknown>

[2022-10-06 17:35:22,558: INFO/MainProcess] Connected to redis://localhost:6379//
[2022-10-06 17:35:22,562: INFO/MainProcess] mingle: searching for neighbors
[2022-10-06 17:35:23,571: INFO/MainProcess] mingle: all alone
[2022-10-06 17:35:23,584: WARNING/MainProcess] /run/media/pirate/STORAGE/System-Application/anaconda3/envs/Django_env/lib/python3.10/site-packages/celery/fixups/django.py:203: UserWarning: Using settings.DEBUG leads to a memory
            leak, never use this setting in production environments!
  warnings.warn('''Using settings.DEBUG leads to a memory

[2022-10-06 17:35:23,584: INFO/MainProcess] celery@Asteria ready.
[2022-10-06 17:38:55,810: INFO/MainProcess] Task services.tasks.start_web_scraping_indeed[0b1a7e27-7829-4962-8935-1914d3fb2153] received
[2022-10-06 17:38:55,812: INFO/ForkPoolWorker-7] ====== WebDriver manager ======
[2022-10-06 17:38:55,856: INFO/ForkPoolWorker-7] Get LATEST chromedriver version for google-chrome 106.0.5249
[2022-10-06 17:39:01,500: INFO/ForkPoolWorker-7] Driver [/home/pirate/.wdm/drivers/chromedriver/linux64/106.0.5249/chromedriver] found in cache
[2022-10-06 17:39:43,262: WARNING/ForkPoolWorker-7] https://in.indeed.com/rc/clk?jk=e78be0bd2d4d8a84&fccid=6576e7250aa78c3c&vjs=3
[2022-10-06 17:40:18,231: WARNING/ForkPoolWorker-7] /run/media/pirate/STORAGE/System-Application/anaconda3/envs/Django_env/lib/python3.10/site-packages/django/db/models/fields/__init__.py:1534: RuntimeWarning: DateTimeField Job.date_posted received a naive datetime (2022-10-05 17:40:00.579203) while time zone support is active.
  warnings.warn(

[2022-10-06 17:40:19,068: INFO/ForkPoolWorker-7] 72 Business Analyst - McKinsey Digital has been added to the database
[2022-10-06 17:40:19,069: WARNING/ForkPoolWorker-7] https://in.indeed.com/rc/clk?jk=e371e9c75190de1d&fccid=6576e7250aa78c3c&vjs=3
[2022-10-06 17:40:42,786: WARNING/ForkPoolWorker-7] /run/media/pirate/STORAGE/System-Application/anaconda3/envs/Django_env/lib/python3.10/site-packages/django/db/models/fields/__init__.py:1534: RuntimeWarning: DateTimeField Job.date_posted received a naive datetime (2022-09-18 17:40:30.874948) while time zone support is active.
  warnings.warn(

[2022-10-06 17:40:43,392: INFO/ForkPoolWorker-7] 73 Executive Assistant has been added to the database
[2022-10-06 17:40:43,394: WARNING/ForkPoolWorker-7] https://in.indeed.com/rc/clk?jk=606910015e7c5e93&fccid=6576e7250aa78c3c&vjs=3
[2022-10-06 17:40:55,207: ERROR/ForkPoolWorker-7] Task services.tasks.start_web_scraping_indeed[0b1a7e27-7829-4962-8935-1914d3fb2153] raised unexpected: IndexError('list index out of range')
Traceback (most recent call last):
  File "/run/media/pirate/STORAGE/System-Application/anaconda3/envs/Django_env/lib/python3.10/site-packages/celery/app/trace.py", line 451, in trace_task
    R = retval = fun(*args, **kwargs)
  File "/run/media/pirate/STORAGE/System-Application/anaconda3/envs/Django_env/lib/python3.10/site-packages/celery/app/trace.py", line 734, in __protected_call__
    return self.run(*args, **kwargs)
  File "/run/media/pirate/STORAGE/Pirate/Code-House/Web-Applications/jobWebsite/jobWebsite/services/tasks.py", line 74, in start_web_scraping_indeed
    date_job_posted_datetime = datetime.now() - timedelta(days=int(date_number[0]))
IndexError: list index out of range
[2022-10-06 17:45:07,445: INFO/MainProcess] Task services.tasks.start_web_scraping_indeed[55ab8a5c-77d2-42c6-a247-b65d8ab8f6eb] received
[2022-10-06 17:45:07,450: INFO/ForkPoolWorker-7] ====== WebDriver manager ======
[2022-10-06 17:45:07,543: INFO/ForkPoolWorker-7] Get LATEST chromedriver version for google-chrome 106.0.5249
[2022-10-06 17:45:13,415: INFO/ForkPoolWorker-7] Driver [/home/pirate/.wdm/drivers/chromedriver/linux64/106.0.5249/chromedriver] found in cache
[2022-10-06 17:45:53,784: WARNING/ForkPoolWorker-7] https://in.indeed.com/rc/clk?jk=e78be0bd2d4d8a84&fccid=6576e7250aa78c3c&vjs=3
[2022-10-06 17:46:30,439: WARNING/ForkPoolWorker-7] /run/media/pirate/STORAGE/System-Application/anaconda3/envs/Django_env/lib/python3.10/site-packages/django/db/models/fields/__init__.py:1534: RuntimeWarning: DateTimeField Job.date_posted received a naive datetime (2022-10-05 17:46:13.020449) while time zone support is active.
  warnings.warn(

[2022-10-06 17:46:30,802: INFO/ForkPoolWorker-7] 74 Business Analyst - McKinsey Digital has been added to the database
[2022-10-06 17:46:30,803: WARNING/ForkPoolWorker-7] https://in.indeed.com/rc/clk?jk=e371e9c75190de1d&fccid=6576e7250aa78c3c&vjs=3
[2022-10-06 17:46:55,016: WARNING/ForkPoolWorker-7] /run/media/pirate/STORAGE/System-Application/anaconda3/envs/Django_env/lib/python3.10/site-packages/django/db/models/fields/__init__.py:1534: RuntimeWarning: DateTimeField Job.date_posted received a naive datetime (2022-09-18 17:46:42.706984) while time zone support is active.
  warnings.warn(

[2022-10-06 17:46:55,621: INFO/ForkPoolWorker-7] 75 Executive Assistant has been added to the database
[2022-10-06 17:46:55,621: WARNING/ForkPoolWorker-7] https://in.indeed.com/rc/clk?jk=606910015e7c5e93&fccid=6576e7250aa78c3c&vjs=3
[2022-10-06 17:47:07,435: ERROR/ForkPoolWorker-7] Task services.tasks.start_web_scraping_indeed[55ab8a5c-77d2-42c6-a247-b65d8ab8f6eb] raised unexpected: IndexError('list index out of range')
Traceback (most recent call last):
  File "/run/media/pirate/STORAGE/System-Application/anaconda3/envs/Django_env/lib/python3.10/site-packages/celery/app/trace.py", line 451, in trace_task
    R = retval = fun(*args, **kwargs)
  File "/run/media/pirate/STORAGE/System-Application/anaconda3/envs/Django_env/lib/python3.10/site-packages/celery/app/trace.py", line 734, in __protected_call__
    return self.run(*args, **kwargs)
  File "/run/media/pirate/STORAGE/Pirate/Code-House/Web-Applications/jobWebsite/jobWebsite/services/tasks.py", line 74, in start_web_scraping_indeed
    if len(date_number) > 0:
IndexError: list index out of range
[2022-10-06 18:07:15,003: INFO/MainProcess] Connected to redis://localhost:6379//
[2022-10-06 18:07:15,005: INFO/MainProcess] mingle: searching for neighbors
[2022-10-06 18:07:16,013: INFO/MainProcess] mingle: all alone
[2022-10-06 18:07:16,029: WARNING/MainProcess] /run/media/pirate/STORAGE/System-Application/anaconda3/envs/Django_env/lib/python3.10/site-packages/celery/fixups/django.py:203: UserWarning: Using settings.DEBUG leads to a memory
            leak, never use this setting in production environments!
  warnings.warn('''Using settings.DEBUG leads to a memory

[2022-10-06 18:07:16,029: INFO/MainProcess] celery@Asteria ready.
[2022-10-06 18:08:42,610: INFO/MainProcess] Task services.tasks.start_web_scraping_indeed[eed5ac35-33b4-483f-997e-0dce4b7c64f2] received
[2022-10-06 18:08:42,613: INFO/ForkPoolWorker-7] ====== WebDriver manager ======
[2022-10-06 18:08:42,653: INFO/ForkPoolWorker-7] Get LATEST chromedriver version for google-chrome 106.0.5249
[2022-10-06 18:08:48,552: INFO/ForkPoolWorker-7] Driver [/home/pirate/.wdm/drivers/chromedriver/linux64/106.0.5249/chromedriver] found in cache
[2022-10-06 18:09:23,536: WARNING/ForkPoolWorker-7] https://in.indeed.com/rc/clk?jk=e78be0bd2d4d8a84&fccid=6576e7250aa78c3c&vjs=3
[2022-10-06 18:09:57,946: WARNING/ForkPoolWorker-7] /run/media/pirate/STORAGE/System-Application/anaconda3/envs/Django_env/lib/python3.10/site-packages/django/db/models/fields/__init__.py:1534: RuntimeWarning: DateTimeField Job.date_posted received a naive datetime (2022-10-05 18:09:40.413144) while time zone support is active.
  warnings.warn(

[2022-10-06 18:09:58,304: INFO/ForkPoolWorker-7] 76 Business Analyst - McKinsey Digital has been added to the database
[2022-10-06 18:09:58,305: WARNING/ForkPoolWorker-7] https://in.indeed.com/rc/clk?jk=e371e9c75190de1d&fccid=6576e7250aa78c3c&vjs=3
[2022-10-06 18:10:21,842: WARNING/ForkPoolWorker-7] /run/media/pirate/STORAGE/System-Application/anaconda3/envs/Django_env/lib/python3.10/site-packages/django/db/models/fields/__init__.py:1534: RuntimeWarning: DateTimeField Job.date_posted received a naive datetime (2022-09-18 18:10:09.859717) while time zone support is active.
  warnings.warn(

[2022-10-06 18:10:22,452: INFO/ForkPoolWorker-7] 77 Executive Assistant has been added to the database
[2022-10-06 18:10:22,453: WARNING/ForkPoolWorker-7] https://in.indeed.com/rc/clk?jk=606910015e7c5e93&fccid=6576e7250aa78c3c&vjs=3
[2022-10-06 18:10:46,238: WARNING/ForkPoolWorker-7] /run/media/pirate/STORAGE/System-Application/anaconda3/envs/Django_env/lib/python3.10/site-packages/django/db/models/fields/__init__.py:1534: RuntimeWarning: DateTimeField Job.date_posted received a naive datetime (2022-10-06 18:10:34.052705) while time zone support is active.
  warnings.warn(

[2022-10-06 18:10:46,848: INFO/ForkPoolWorker-7] 78 Junior Capabilities & Insights Analyst - Automotive & Assemb... has been added to the database
[2022-10-06 18:10:46,850: WARNING/ForkPoolWorker-7] https://in.indeed.com/rc/clk?jk=9879f392ad8514cd&fccid=6576e7250aa78c3c&vjs=3
[2022-10-06 18:11:10,738: WARNING/ForkPoolWorker-7] /run/media/pirate/STORAGE/System-Application/anaconda3/envs/Django_env/lib/python3.10/site-packages/django/db/models/fields/__init__.py:1534: RuntimeWarning: DateTimeField Job.date_posted received a naive datetime (2022-09-06 18:10:58.757215) while time zone support is active.
  warnings.warn(

[2022-10-06 18:11:11,102: INFO/ForkPoolWorker-7] 79 Research Science Analyst - Panorama Financial Institutions C... has been added to the database
[2022-10-06 18:11:11,103: WARNING/ForkPoolWorker-7] https://in.indeed.com/rc/clk?jk=299d47822ca40531&fccid=6576e7250aa78c3c&vjs=3
[2022-10-06 18:11:35,124: WARNING/ForkPoolWorker-7] /run/media/pirate/STORAGE/System-Application/anaconda3/envs/Django_env/lib/python3.10/site-packages/django/db/models/fields/__init__.py:1534: RuntimeWarning: DateTimeField Job.date_posted received a naive datetime (2022-09-21 18:11:23.020046) while time zone support is active.
  warnings.warn(

[2022-10-06 18:11:35,734: INFO/ForkPoolWorker-7] 80 Process Excellence Manager has been added to the database
[2022-10-06 18:11:35,735: WARNING/ForkPoolWorker-7] https://in.indeed.com/rc/clk?jk=2941417f477420e7&fccid=6576e7250aa78c3c&vjs=3
[2022-10-06 18:11:59,345: WARNING/ForkPoolWorker-7] /run/media/pirate/STORAGE/System-Application/anaconda3/envs/Django_env/lib/python3.10/site-packages/django/db/models/fields/__init__.py:1534: RuntimeWarning: DateTimeField Job.date_posted received a naive datetime (2022-09-29 18:11:47.462937) while time zone support is active.
  warnings.warn(

[2022-10-06 18:11:59,965: INFO/ForkPoolWorker-7] 81 Data Scientist - QuantumBlack has been added to the database
[2022-10-06 18:11:59,966: WARNING/ForkPoolWorker-7] https://in.indeed.com/rc/clk?jk=1f52c34fa295cae4&fccid=6576e7250aa78c3c&vjs=3
[2022-10-06 18:12:23,916: WARNING/ForkPoolWorker-7] /run/media/pirate/STORAGE/System-Application/anaconda3/envs/Django_env/lib/python3.10/site-packages/django/db/models/fields/__init__.py:1534: RuntimeWarning: DateTimeField Job.date_posted received a naive datetime (2022-09-06 18:12:11.800639) while time zone support is active.
  warnings.warn(

[2022-10-06 18:12:26,700: INFO/ForkPoolWorker-7] 82 Associate Life Sciences has been added to the database
[2022-10-06 18:12:26,700: WARNING/ForkPoolWorker-7] https://in.indeed.com/rc/clk?jk=5dd47a07270edfa5&fccid=6576e7250aa78c3c&vjs=3
[2022-10-06 18:12:50,930: WARNING/ForkPoolWorker-7] /run/media/pirate/STORAGE/System-Application/anaconda3/envs/Django_env/lib/python3.10/site-packages/django/db/models/fields/__init__.py:1534: RuntimeWarning: DateTimeField Job.date_posted received a naive datetime (2022-09-21 18:12:38.395575) while time zone support is active.
  warnings.warn(

[2022-10-06 18:12:51,524: INFO/ForkPoolWorker-7] 83 Office Services Administrator has been added to the database
[2022-10-06 18:12:51,526: WARNING/ForkPoolWorker-7] https://in.indeed.com/rc/clk?jk=83996f0771385526&fccid=6576e7250aa78c3c&vjs=3
[2022-10-06 18:13:15,248: WARNING/ForkPoolWorker-7] /run/media/pirate/STORAGE/System-Application/anaconda3/envs/Django_env/lib/python3.10/site-packages/django/db/models/fields/__init__.py:1534: RuntimeWarning: DateTimeField Job.date_posted received a naive datetime (2022-09-30 18:13:03.307279) while time zone support is active.
  warnings.warn(

[2022-10-06 18:13:15,860: INFO/ForkPoolWorker-7] 84 Proposal Specialist has been added to the database
[2022-10-06 18:13:15,861: WARNING/ForkPoolWorker-7] https://in.indeed.com/rc/clk?jk=df1d031a09d62afb&fccid=6576e7250aa78c3c&vjs=3
[2022-10-06 18:13:39,581: WARNING/ForkPoolWorker-7] /run/media/pirate/STORAGE/System-Application/anaconda3/envs/Django_env/lib/python3.10/site-packages/django/db/models/fields/__init__.py:1534: RuntimeWarning: DateTimeField Job.date_posted received a naive datetime (2022-10-04 18:13:27.556349) while time zone support is active.
  warnings.warn(

[2022-10-06 18:13:40,202: INFO/ForkPoolWorker-7] 85 Human Resources Generalist (Benefits) - INO has been added to the database
[2022-10-06 18:13:40,203: WARNING/ForkPoolWorker-7] https://in.indeed.com/rc/clk?jk=a8aef4deb231583a&fccid=6576e7250aa78c3c&vjs=3
[2022-10-06 18:14:04,453: WARNING/ForkPoolWorker-7] /run/media/pirate/STORAGE/System-Application/anaconda3/envs/Django_env/lib/python3.10/site-packages/django/db/models/fields/__init__.py:1534: RuntimeWarning: DateTimeField Job.date_posted received a naive datetime (2022-09-06 18:13:51.972241) while time zone support is active.
  warnings.warn(

[2022-10-06 18:14:05,077: INFO/ForkPoolWorker-7] 86 Capabilities and Insights Analyst_Payments Asia Hub_Gurugram has been added to the database
[2022-10-06 18:14:05,078: WARNING/ForkPoolWorker-7] https://in.indeed.com/rc/clk?jk=e45bf89d0e713aca&fccid=6576e7250aa78c3c&vjs=3
[2022-10-06 18:14:29,432: WARNING/ForkPoolWorker-7] /run/media/pirate/STORAGE/System-Application/anaconda3/envs/Django_env/lib/python3.10/site-packages/django/db/models/fields/__init__.py:1534: RuntimeWarning: DateTimeField Job.date_posted received a naive datetime (2022-09-21 18:14:17.343662) while time zone support is active.
  warnings.warn(

[2022-10-06 18:14:30,761: INFO/ForkPoolWorker-7] 87 Capabilities & Insights Team Leader - Client Capabilities Ne... has been added to the database
[2022-10-06 18:14:30,764: WARNING/ForkPoolWorker-7] https://in.indeed.com/rc/clk?jk=54624aff233cb1cb&fccid=6576e7250aa78c3c&vjs=3
[2022-10-06 18:14:54,842: WARNING/ForkPoolWorker-7] /run/media/pirate/STORAGE/System-Application/anaconda3/envs/Django_env/lib/python3.10/site-packages/django/db/models/fields/__init__.py:1534: RuntimeWarning: DateTimeField Job.date_posted received a naive datetime (2022-09-06 18:14:42.587505) while time zone support is active.
  warnings.warn(

[2022-10-06 18:14:55,447: INFO/ForkPoolWorker-7] 88 Analyst – OrgSolutions has been added to the database
[2022-10-06 18:14:55,448: WARNING/ForkPoolWorker-7] https://in.indeed.com/rc/clk?jk=ac65f9ceeb139d35&fccid=6576e7250aa78c3c&vjs=3
[2022-10-06 18:15:19,318: WARNING/ForkPoolWorker-7] /run/media/pirate/STORAGE/System-Application/anaconda3/envs/Django_env/lib/python3.10/site-packages/django/db/models/fields/__init__.py:1534: RuntimeWarning: DateTimeField Job.date_posted received a naive datetime (2022-09-06 18:15:07.196821) while time zone support is active.
  warnings.warn(

[2022-10-06 18:15:21,725: INFO/ForkPoolWorker-7] 89 Receptionist has been added to the database
[2022-10-06 18:15:21,727: WARNING/ForkPoolWorker-7] https://in.indeed.com/rc/clk?jk=20bc8525ce130ae7&fccid=6576e7250aa78c3c&vjs=3
[2022-10-06 18:15:45,574: WARNING/ForkPoolWorker-7] /run/media/pirate/STORAGE/System-Application/anaconda3/envs/Django_env/lib/python3.10/site-packages/django/db/models/fields/__init__.py:1534: RuntimeWarning: DateTimeField Job.date_posted received a naive datetime (2022-09-06 18:15:33.484800) while time zone support is active.
  warnings.warn(

[2022-10-06 18:15:46,711: INFO/ForkPoolWorker-7] 90 Associate - Sustainability has been added to the database
[2022-10-06 18:15:46,711: INFO/ForkPoolWorker-7] None is not active
[2022-10-06 18:15:46,774: INFO/ForkPoolWorker-7] Task services.tasks.start_web_scraping_indeed[eed5ac35-33b4-483f-997e-0dce4b7c64f2] succeeded in 424.1614704120002s: None
